Workbook

Sheet 1.HAFTA
A1: TALEBE TAKİP SİSTEMİ 2024-2025 | AE1: Amsterdam Saray
A2: 1.HAFTA | C2: SABAH NAMAZI PROGRAMLARI | J2: AKŞAM NAMAZI PROĞRAMLARI | Q2: YATSI NAMAZI PROGRAMLARI | X2: HATİM | AE2: 1.HAFTA ORTALAMALAR
A3: NO | B3: ADI SOYADI | C3: PAZARTESİ | D3: SALI | E3: ÇARŞAMBA | F3: PERŞEMBE | G3: CUMA | H3: CUMARTESİ | I3: PAZAR | J3: PAZARTESİ | K3: SALI | L3: ÇARŞAMBA | M3: PERŞEMBE | N3: CUMA | O3: CUMARTESİ | P3: PAZAR | Q3: PAZARTESİ | R3: SALI | S3: ÇARŞAMBA | T3: PERŞEMBE | U3: CUMA | V3: CUMARTESİ | W3: PAZAR | X3: PAZARTESİ | Y3: SALI | Z3: ÇARŞAMBA | AA3: PERŞEMBE | AB3: CUMA | AC3: CUMARTESİ | AD3: CUMARTESİ | AE3: SABAH | AF3: AKŞAM | AG3: YATSI | AH3: HATİM | AI3: NAMAZ
A4: 1 | B4: Abdullah Koşar | C4: i | D4: 0 | E4: 0 | F4: 0 | G4: 0 | H4: 0 | I4: i | Q4: 0 | R4: 0 | S4: 0 | T4: i | U4: 0 | V4: i | W4: i | X4: i | Y4: 0 | Z4: i | AA4: i | AB4: i | AC4: 0 | AD4: i | AE4: =AVERAGE(C4:I4) -> 0 | AF4: =AVERAGE(J4:P4) -> #DIV/0! | AG4: =AVERAGE(Q4:W4) -> 0 | AH4: =AVERAGE(X4:AD4) -> 0 | AI4: =AVERAGE(C4:W4) -> 0
A5: 2 | B5: Ahmet Arif Ozmen | C5: i | D5: i | E5: i | F5: i | G5: i | H5: i | I5: i | Q5: 1 | R5: 1 | S5: 1 | T5: i | U5: 1 | V5: i | W5: i | X5: i | Y5: i | Z5: i | AA5: i | AB5: i | AC5: i | AD5: i | AE5: =AVERAGE(C5:I5) -> #DIV/0! | AF5: =AVERAGE(J5:P5) -> #DIV/0! | AG5: =AVERAGE(Q5:W5) -> 1 | AH5: =AVERAGE(X5:AD5) -> #DIV/0! | AI5: =AVERAGE(C5:W5) -> 1 | AK5: 45719 | AL5: 45725
A6: 3 | B6: Alihan Uysal | C6: i | D6: 1 | E6: 1 | F6: 1 | G6: 0 | H6: b | I6: i | Q6: 1 | R6: 1 | S6: 1 | T6: i | U6: 0 | V6: i | W6: i | X6: i | Y6: 1 | Z6: i | AA6: i | AB6: i | AC6: 1 | AD6: i | AE6: =AVERAGE(C6:I6) -> 0.75 | AF6: =AVERAGE(J6:P6) -> #DIV/0! | AG6: =AVERAGE(Q6:W6) -> 0.75 | AH6: =AVERAGE(X6:AD6) -> 1 | AI6: =AVERAGE(C6:W6) -> 0.75
A7: 4 | B7: Ammaar Ahmad | C7: i | D7: 1 | E7: 1 | F7: 1 | G7: 1 | H7: 1 | I7: i | Q7: 1 | R7: 1 | S7: 1 | T7: i | U7: 1 | V7: i | W7: i | X7: i | Y7: 1 | Z7: i | AA7: i | AB7: i | AC7: 1 | AD7: i | AE7: =AVERAGE(C7:I7) -> 1 | AF7: =AVERAGE(J7:P7) -> #DIV/0! | AG7: =AVERAGE(Q7:W7) -> 1 | AH7: =AVERAGE(X7:AD7) -> 1 | AI7: =AVERAGE(C7:W7) -> 1
A8: 5 | B8: Ekrem Altıntaş | C8: i | D8: 0 | E8: 1 | F8: 0 | G8: 0 | H8: 0 | I8: i | Q8: 1 | R8: 1 | S8: 1 | T8: i | U8: 1 | V8: i | W8: i | X8: i | Y8: 0 | Z8: i | AA8: i | AB8: i | AC8: 1 | AD8: i | AE8: =AVERAGE(C8:I8) -> 0.2 | AF8: =AVERAGE(J8:P8) -> #DIV/0! | AG8: =AVERAGE(Q8:W8) -> 1 | AH8: =AVERAGE(X8:AD8) -> 0.5 | AI8: =AVERAGE(C8:W8) -> 0.55555556
A9: 6 | B9: Emirhan Sak | C9: i | D9: i | E9: 1 | F9: 1 | G9: 0 | H9: 0 | I9: i | Q9: 1 | R9: 1 | S9: 1 | T9: i | U9: 0 | V9: i | W9: i | X9: i | Y9: i | Z9: i | AA9: i | AB9: i | AC9: 0 | AD9: i | AE9: =AVERAGE(C9:I9) -> 0.5 | AF9: =AVERAGE(J9:P9) -> #DIV/0! | AG9: =AVERAGE(Q9:W9) -> 0.75 | AH9: =AVERAGE(X9:AD9) -> 0 | AI9: =AVERAGE(C9:W9) -> 0.625
A10: 7 | B10: Eymen Göğebakan | C10: i | D10: i | E10: 1 | F10: 0 | G10: 0 | H10: 1 | I10: i | Q10: i | R10: 1 | S10: 1 | T10: i | U10: 0 | V10: i | W10: i | X10: i | Y10: i | Z10: i | AA10: i | AB10: i | AC10: 1 | AD10: i | AE10: =AVERAGE(C10:I10) -> 0.5 | AF10: =AVERAGE(J10:P10) -> #DIV/0! | AG10: =AVERAGE(Q10:W10) -> 0.66666667 | AH10: =AVERAGE(X10:AD10) -> 1 | AI10: =AVERAGE(C10:W10) -> 0.57142857
A11: 8 | B11: Mehmet Sak | C11: i | D11: 1 | E11: 1 | F11: 1 | G11: 1 | H11: 1 | I11: i | Q11: 1 | R11: 1 | S11: i | T11: i | U11: 1 | V11: i | W11: i | X11: i | Y11: 1 | Z11: i | AA11: i | AB11: i | AC11: 1 | AD11: i | AE11: =AVERAGE(C11:I11) -> 1 | AF11: =AVERAGE(J11:P11) -> #DIV/0! | AG11: =AVERAGE(Q11:W11) -> 1 | AH11: =AVERAGE(X11:AD11) -> 1 | AI11: =AVERAGE(C11:W11) -> 1
A12: 9 | B12: Mohammed Abdi Hakim | C12: i | D12: 1 | E12: 1 | F12: 1 | G12: 1 | H12: 0 | I12: i | Q12: 1 | R12: 1 | S12: 1 | T12: i | U12: 1 | V12: i | W12: i | X12: i | Y12: 1 | Z12: i | AA12: i | AB12: i | AC12: 1 | AD12: i | AE12: =AVERAGE(C12:I12) -> 0.8 | AF12: =AVERAGE(J12:P12) -> #DIV/0! | AG12: =AVERAGE(Q12:W12) -> 1 | AH12: =AVERAGE(X12:AD12) -> 1 | AI12: =AVERAGE(C12:W12) -> 0.88888889
A13: 10 | B13: Rıdvan Sönmez | C13: i | D13: 1 | E13: 1 | F13: 1 | G13: 1 | H13: 1 | I13: i | Q13: 1 | R13: 1 | S13: 1 | T13: i | U13: 1 | V13: i | W13: i | X13: i | Y13: 1 | Z13: i | AA13: i | AB13: i | AC13: 1 | AD13: i | AE13: =AVERAGE(C13:I13) -> 1 | AF13: =AVERAGE(J13:P13) -> #DIV/0! | AG13: =AVERAGE(Q13:W13) -> 1 | AH13: =AVERAGE(X13:AD13) -> 1 | AI13: =AVERAGE(C13:W13) -> 1
A14: 11 | B14: Tayyip Sönmez | C14: i | D14: 1 | E14: i | F14: 0 | G14: i | H14: i | I14: i | J14: i | K14: i | L14: i | M14: i | N14: i | O14: i | P14: i | Q14: 1 | R14: 1 | S14: i | T14: i | U14: i | V14: i | W14: i | X14: i | Y14: 1 | Z14: i | AA14: i | AB14: i | AC14: i | AD14: i | AE14: =AVERAGE(C14:I14) -> 0.5 | AF14: =AVERAGE(J14:P14) -> #DIV/0! | AG14: =AVERAGE(Q14:W14) -> 1 | AH14: =AVERAGE(X14:AD14) -> 1 | AI14: =AVERAGE(C14:W14) -> 0.75
A15: 12 | B15: Waffi Talib | C15: i | D15: i | E15: i | F15: 1 | G15: 1 | H15: 0 | I15: i | Q15: 1 | R15: i | S15: 1 | T15: i | U15: 0 | V15: i | W15: i | X15: i | Y15: i | Z15: i | AA15: i | AB15: i | AC15: 1 | AD15: i | AE15: =AVERAGE(C15:I15) -> 0.66666667 | AF15: =AVERAGE(J15:P15) -> #DIV/0! | AG15: =AVERAGE(Q15:W15) -> 0.66666667 | AH15: =AVERAGE(X15:AD15) -> 1 | AI15: =AVERAGE(C15:W15) -> 0.66666667
A16: 13 | B16: Ahmet Enes Küçüktepe | C16: i | D16: 1 | E16: B | F16: 1 | G16: 0 | H16: 0 | I16: i | Q16: 1 | R16: I | S16: 1 | T16: i | U16: 1 | V16: i | W16: i | X16: i | Y16: 1 | Z16: i | AA16: i | AB16: i | AC16: 0 | AD16: i | AE16: =AVERAGE(C16:I16) -> 0.5 | AF16: =AVERAGE(J16:P16) -> #DIV/0! | AG16: =AVERAGE(Q16:W16) -> 1 | AH16: =AVERAGE(X16:AD16) -> 0.5 | AI16: =AVERAGE(C16:W16) -> 0.71428571
A17: 14 | B17: Abdulkerim Karazehir | C17: i | D17: 0 | E17: 1 | F17: 0 | G17: i | H17: 0 | I17: i | Q17: 0 | R17: o | S17: 0 | T17: i | U17: 0 | V17: i | W17: i | X17: i | Y17: 0 | Z17: i | AA17: i | AB17: i | AC17: 1 | AD17: i | AE17: =AVERAGE(C17:I17) -> 0.25 | AF17: =AVERAGE(J17:P17) -> #DIV/0! | AG17: =AVERAGE(Q17:W17) -> 0 | AH17: =AVERAGE(X17:AD17) -> 0.5 | AI17: =AVERAGE(C17:W17) -> 0.14285714
A18: 15 | B18: Berat Basan | C18: i | D18: i | E18: 0 | F18: 0 | G18: 0 | H18: 0 | I18: i | Q18: 0 | R18: 0 | S18: 0 | T18: i | U18: 0 | V18: i | W18: i | X18: i | Y18: i | Z18: i | AA18: i | AB18: i | AC18: 0 | AD18: i | AE18: =AVERAGE(C18:I18) -> 0 | AF18: =AVERAGE(J18:P18) -> #DIV/0! | AG18: =AVERAGE(Q18:W18) -> 0 | AH18: =AVERAGE(X18:AD18) -> 0 | AI18: =AVERAGE(C18:W18) -> 0
A19: 16 | B19: Burhan Çevik | C19: i | D19: 1 | E19: 0 | F19: 1 | G19: 0 | H19: 0 | I19: i | Q19: 1 | R19: 0 | S19: 0 | T19: i | U19: 1 | V19: i | W19: i | X19: i | Y19: 1 | Z19: i | AA19: i | AB19: i | AC19: 0 | AD19: i | AE19: =AVERAGE(C19:I19) -> 0.4 | AF19: =AVERAGE(J19:P19) -> #DIV/0! | AG19: =AVERAGE(Q19:W19) -> 0.5 | AH19: =AVERAGE(X19:AD19) -> 0.5 | AI19: =AVERAGE(C19:W19) -> 0.44444444
A20: 17 | B20: Enes Bakar | C20: i | D20: 0 | E20: 0 | F20: 1 | G20: 0 | H20: 0 | I20: i | Q20: 0 | R20: 0 | S20: 0 | T20: i | U20: 0 | V20: i | W20: i | X20: i | Y20: 0 | Z20: i | AA20: i | AB20: i | AC20: 1 | AD20: i | AE20: =AVERAGE(C20:I20) -> 0.2 | AF20: =AVERAGE(J20:P20) -> #DIV/0! | AG20: =AVERAGE(Q20:W20) -> 0 | AH20: =AVERAGE(X20:AD20) -> 0.5 | AI20: =AVERAGE(C20:W20) -> 0.11111111
A21: 18 | B21: Hüseyin Özdemir | C21: i | D21: 0 | E21: 0 | F21: 1 | G21: 0 | H21: 0 | I21: i | Q21: 1 | R21: 0 | S21: 1 | T21: i | U21: 0 | V21: i | W21: i | X21: i | Y21: 0 | Z21: i | AA21: i | AB21: i | AC21: 1 | AD21: i | AE21: =AVERAGE(C21:I21) -> 0.2 | AF21: =AVERAGE(J21:P21) -> #DIV/0! | AG21: =AVERAGE(Q21:W21) -> 0.5 | AH21: =AVERAGE(X21:AD21) -> 0.5 | AI21: =AVERAGE(C21:W21) -> 0.33333333
A22: 19 | B22: Yahya Yıldız | C22: i | D22: 1 | E22: 0 | F22: i | G22: 0 | H22: 0 | I22: i | Q22: o | R22: 0 | S22: i | T22: i | U22: 1 | V22: i | W22: i | X22: i | Y22: 1 | Z22: i | AA22: i | AB22: i | AC22: 1 | AD22: i | AE22: =AVERAGE(C22:I22) -> 0.25 | AF22: =AVERAGE(J22:P22) -> #DIV/0! | AG22: =AVERAGE(Q22:W22) -> 0.5 | AH22: =AVERAGE(X22:AD22) -> 1 | AI22: =AVERAGE(C22:W22) -> 0.33333333
A23: 20 | B23: Yakup Karazehir | C23: i | D23: 1 | E23: 1 | F23: 1 | G23: 1 | H23: 1 | I23: i | Q23: 1 | R23: i | S23: i | T23: i | U23: 1 | V23: i | W23: i | X23: i | Y23: 1 | Z23: i | AA23: i | AB23: i | AC23: 1 | AD23: i | AE23: =AVERAGE(C23:I23) -> 1 | AF23: =AVERAGE(J23:P23) -> #DIV/0! | AG23: =AVERAGE(Q23:W23) -> 1 | AH23: =AVERAGE(X23:AD23) -> 1 | AI23: =AVERAGE(C23:W23) -> 1
A24: 21 | B24: Abdussamed Arslan | C24: i | D24: i | E24: 0 | F24: 0 | G24: 1 | H24: 1 | I24: i | Q24: i | R24: 0 | S24: 0 | T24: i | U24: 0 | V24: i | W24: i | X24: i | Y24: i | Z24: i | AA24: i | AB24: i | AC24: 0 | AD24: i | AE24: =AVERAGE(C24:I24) -> 0.5 | AF24: =AVERAGE(J24:P24) -> #DIV/0! | AG24: =AVERAGE(Q24:W24) -> 0 | AH24: =AVERAGE(X24:AD24) -> 0 | AI24: =AVERAGE(C24:W24) -> 0.28571429
A25: 22 | B25: Abdussamed Erdem | C25: i | D25: i | E25: i | F25: i | G25: 1 | H25: 1 | I25: i | Q25: i | R25: i | S25: i | T25: i | U25: i | V25: i | W25: i | X25: i | Y25: i | Z25: i | AA25: i | AB25: i | AC25: 1 | AD25: i | AE25: =AVERAGE(C25:I25) -> 1 | AF25: =AVERAGE(J25:P25) -> #DIV/0! | AG25: =AVERAGE(Q25:W25) -> #DIV/0! | AH25: =AVERAGE(X25:AD25) -> 1 | AI25: =AVERAGE(C25:W25) -> 1
A26: 23 | B26: Ahmet Boyacıoğlu | C26: i | D26: 1 | E26: 1 | F26: 1 | G26: i | H26: i | I26: i | Q26: 1 | R26: 0 | S26: 1 | T26: i | U26: i | V26: i | W26: i | X26: i | Y26: 0 | Z26: i | AA26: i | AB26: i | AC26: i | AD26: i | AE26: =AVERAGE(C26:I26) -> 1 | AF26: =AVERAGE(J26:P26) -> #DIV/0! | AG26: =AVERAGE(Q26:W26) -> 0.66666667 | AH26: =AVERAGE(X26:AD26) -> 0 | AI26: =AVERAGE(C26:W26) -> 0.83333333
A27: 24 | B27: Ahmet Kökçü | C27: i | D27: 1 | E27: 1 | F27: 1 | G27: 1 | H27: 1 | I27: i | Q27: 1 | R27: 1 | S27: 1 | T27: i | U27: i | V27: i | W27: i | X27: i | Y27: 1 | Z27: i | AA27: i | AB27: i | AC27: 1 | AD27: i | AE27: =AVERAGE(C27:I27) -> 1 | AF27: =AVERAGE(J27:P27) -> #DIV/0! | AG27: =AVERAGE(Q27:W27) -> 1 | AH27: =AVERAGE(X27:AD27) -> 1 | AI27: =AVERAGE(C27:W27) -> 1
A28: 25 | B28: Fatih Burcu | C28: i | D28: 1 | E28: 1 | F28: 1 | G28: 1 | H28: 1 | I28: i | Q28: 1 | R28: i | S28: i | T28: i | U28: i | V28: i | W28: i | X28: i | Y28: 1 | Z28: i | AA28: i | AB28: i | AC28: 1 | AD28: i | AE28: =AVERAGE(C28:I28) -> 1 | AF28: =AVERAGE(J28:P28) -> #DIV/0! | AG28: =AVERAGE(Q28:W28) -> 1 | AH28: =AVERAGE(X28:AD28) -> 1 | AI28: =AVERAGE(C28:W28) -> 1
A29: 26 | B29: Fehmi Kütük | C29: i | D29: 1 | E29: 1 | F29: 1 | G29: 1 | H29: i | I29: i | Q29: 1 | R29: 1 | S29: 1 | T29: i | U29: i | V29: i | W29: i | X29: i | Y29: 0 | Z29: i | AA29: i | AB29: i | AC29: i | AD29: i | AE29: =AVERAGE(C29:I29) -> 1 | AF29: =AVERAGE(J29:P29) -> #DIV/0! | AG29: =AVERAGE(Q29:W29) -> 1 | AH29: =AVERAGE(X29:AD29) -> 0 | AI29: =AVERAGE(C29:W29) -> 1
A30: 27 | B30: Mehmet Cakmak | C30: i | D30: i | E30: i | F30: 1 | G30: 1 | H30: 1 | I30: i | Q30: i | R30: 0 | S30: 1 | T30: i | U30: 1 | V30: i | W30: i | X30: i | Y30: i | Z30: i | AA30: i | AB30: i | AC30: 1 | AD30: i | AE30: =AVERAGE(C30:I30) -> 1 | AF30: =AVERAGE(J30:P30) -> #DIV/0! | AG30: =AVERAGE(Q30:W30) -> 0.66666667 | AH30: =AVERAGE(X30:AD30) -> 1 | AI30: =AVERAGE(C30:W30) -> 0.83333333
A31: 28 | B31: Rasit Aldirmaz | C31: i | D31: i | E31: i | F31: i | G31: 1 | H31: 1 | I31: i | Q31: i | R31: i | S31: i | T31: i | U31: 0 | V31: i | W31: i | X31: i | Y31: i | Z31: i | AA31: i | AB31: i | AC31: 0 | AD31: i | AE31: =AVERAGE(C31:I31) -> 1 | AF31: =AVERAGE(J31:P31) -> #DIV/0! | AG31: =AVERAGE(Q31:W31) -> 0 | AH31: =AVERAGE(X31:AD31) -> 0 | AI31: =AVERAGE(C31:W31) -> 0.66666667
A32: 29 | B32: Tunahan Altun | C32: i | D32: 1 | E32: 1 | F32: 0 | G32: 1 | H32: 1 | I32: i | Q32: 1 | R32: 1 | S32: 1 | T32: i | U32: 0 | V32: i | W32: i | X32: i | Y32: 1 | Z32: i | AA32: i | AB32: i | AC32: 1 | AD32: i | AE32: =AVERAGE(C32:I32) -> 0.8 | AF32: =AVERAGE(J32:P32) -> #DIV/0! | AG32: =AVERAGE(Q32:W32) -> 0.75 | AH32: =AVERAGE(X32:AD32) -> 1 | AI32: =AVERAGE(C32:W32) -> 0.77777778
A33: 30 | B33: Yusuf Emin Doğan | C33: i | D33: 1 | E33: 0 | F33: i | G33: i | H33: i | I33: i | Q33: 0 | R33: i | S33: i | T33: i | U33: i | V33: i | W33: i | X33: i | Y33: 1 | Z33: i | AA33: i | AB33: i | AC33: i | AD33: i | AE33: =AVERAGE(C33:I33) -> 0.5 | AF33: =AVERAGE(J33:P33) -> #DIV/0! | AG33: =AVERAGE(Q33:W33) -> 0 | AH33: =AVERAGE(X33:AD33) -> 1 | AI33: =AVERAGE(C33:W33) -> 0.33333333
A34: 31 | B34: Ahmet Doğan | C34: i | D34: 1 | E34: 1 | F34: 1 | G34: 1 | H34: 1 | I34: i | Q34: 1 | R34: 1 | S34: 1 | T34: i | U34: 1 | V34: i | W34: i | X34: i | Y34: 1 | Z34: i | AA34: i | AB34: i | AC34: 0 | AD34: i | AE34: =AVERAGE(C34:I34) -> 1 | AF34: =AVERAGE(J34:P34) -> #DIV/0! | AG34: =AVERAGE(Q34:W34) -> 1 | AH34: =AVERAGE(X34:AD34) -> 0.5 | AI34: =AVERAGE(C34:W34) -> 1
A35: 32 | B35: Cihan Boorsma | C35: i | D35: 0 | E35: 1 | F35: 1 | G35: 1 | H35: 0 | I35: i | Q35: 1 | R35: 1 | S35: 1 | T35: i | U35: 1 | V35: i | W35: i | X35: i | Y35: 1 | Z35: i | AA35: i | AB35: i | AC35: 1 | AD35: i | AE35: =AVERAGE(C35:I35) -> 0.6 | AF35: =AVERAGE(J35:P35) -> #DIV/0! | AG35: =AVERAGE(Q35:W35) -> 1 | AH35: =AVERAGE(X35:AD35) -> 1 | AI35: =AVERAGE(C35:W35) -> 0.77777778
A36: 33 | B36: Mehmethan Gür | C36: i | D36: 0 | E36: 1 | F36: 1 | G36: 1 | H36: 1 | I36: i | Q36: 1 | R36: 0 | S36: 1 | T36: i | U36: 1 | V36: i | W36: i | X36: i | Y36: 0 | Z36: i | AA36: i | AB36: i | AC36: 0 | AD36: i | AE36: =AVERAGE(C36:I36) -> 0.8 | AF36: =AVERAGE(J36:P36) -> #DIV/0! | AG36: =AVERAGE(Q36:W36) -> 0.75 | AH36: =AVERAGE(X36:AD36) -> 0 | AI36: =AVERAGE(C36:W36) -> 0.77777778 | AM36: =-AM510 -> 0
A37: 34 | B37: Melih Taş | C37: i | D37: 1 | E37: 1 | F37: 1 | G37: 1 | H37: 1 | I37: i | Q37: 1 | R37: 0 | S37: 1 | T37: i | U37: 0 | V37: i | W37: i | X37: i | Y37: 1 | Z37: i | AA37: i | AB37: i | AC37: 0 | AD37: i | AE37: =AVERAGE(C37:I37) -> 1 | AF37: =AVERAGE(J37:P37) -> #DIV/0! | AG37: =AVERAGE(Q37:W37) -> 0.5 | AH37: =AVERAGE(X37:AD37) -> 0.5 | AI37: =AVERAGE(C37:W37) -> 0.77777778
A38: 35 | B38: Melih Uzun | C38: i | D38: 1 | E38: 1 | F38: 1 | G38: 1 | H38: i | I38: i | Q38: 1 | R38: 1 | S38: 1 | T38: i | U38: 1 | V38: i | W38: i | X38: i | Y38: 1 | Z38: i | AA38: i | AB38: i | AC38: i | AD38: i | AE38: =AVERAGE(C38:I38) -> 1 | AF38: =AVERAGE(J38:P38) -> #DIV/0! | AG38: =AVERAGE(Q38:W38) -> 1 | AH38: =AVERAGE(X38:AD38) -> 1 | AI38: =AVERAGE(C38:W38) -> 1
A39: 36 | B39: Mucahit Kan | C39: i | D39: 1 | E39: 0 | F39: 0 | G39: 1 | H39: 0 | I39: i | Q39: i | R39: 0 | S39: 0 | T39: i | U39: 1 | V39: i | W39: i | X39: i | Y39: 1 | Z39: i | AA39: i | AB39: i | AC39: 0 | AD39: i | AE39: =AVERAGE(C39:I39) -> 0.4 | AF39: =AVERAGE(J39:P39) -> #DIV/0! | AG39: =AVERAGE(Q39:W39) -> 0.33333333 | AH39: =AVERAGE(X39:AD39) -> 0.5 | AI39: =AVERAGE(C39:W39) -> 0.375
A40: 37 | B40: Oğuzhan Üzümcü | C40: i | D40: 1 | E40: 1 | F40: 1 | G40: 1 | H40: 1 | I40: i | Q40: 1 | R40: 1 | S40: 1 | T40: i | U40: 1 | V40: i | W40: i | X40: i | Y40: 1 | Z40: i | AA40: i | AB40: i | AC40: 0 | AD40: i | AE40: =AVERAGE(C40:I40) -> 1 | AF40: =AVERAGE(J40:P40) -> #DIV/0! | AG40: =AVERAGE(Q40:W40) -> 1 | AH40: =AVERAGE(X40:AD40) -> 0.5 | AI40: =AVERAGE(C40:W40) -> 1
...

Sheet 2.HAFTA
A1: =('1.HAFTA'!A1:AD1) -> TALEBE TAKİP SİSTEMİ 2024-2025 | AE1: =('1.HAFTA'!AE1:AI1) -> Amsterdam Saray
A2: 2.HAFTA | C2: SABAH NAMAZI PROGRAMLARI | J2: AKŞAM NAMAI PROĞRAMLARI | Q2: YATSI NAMAZI PROGRAMLARI | X2: HATİM | AE2: 2.HAFTA ORTALAMALAR
A3: NO | B3: ADI SOYADI | C3: PAZARTESİ | D3: SALI | E3: ÇARŞAMBA | F3: PERŞEMBE | G3: CUMA | H3: CUMARTESİ | I3: PAZAR | J3: PAZARTESİ | K3: SALI | L3: ÇARŞAMBA | M3: PERŞEMBE | N3: CUMA | O3: CUMARTESİ | P3: PAZAR | Q3: PAZARTESİ | R3: SALI | S3: ÇARŞAMBA | T3: PERŞEMBE | U3: CUMA | V3: CUMARTESİ | W3: PAZAR | X3: PAZARTESİ | Y3: SALI | Z3: ÇARŞAMBA | AA3: PERŞEMBE | AB3: CUMA | AC3: CUMARTESİ | AD3: PAZAR | AE3: SABAH | AF3: AKŞAM | AG3: YATSI | AH3: HATİM | AI3: NAMAZ
A4: 1 | B4: ='1.HAFTA'!B4 -> Abdullah Koşar | C4: i | D4: 0 | E4: 0 | F4: 0 | G4: 0 | H4: i | I4: i | Q4: 0 | R4: i | S4: i | T4: 0 | U4: 0 | V4: i | W4: i | X4: i | Y4: i | Z4: i | AA4: 0 | AB4: i | AC4: i | AD4: i | AE4: =AVERAGE(C4:I4) -> 0 | AF4: =AVERAGE(J4:P4) -> #DIV/0! | AG4: =AVERAGE(Q4:W4) -> 0 | AH4: =AVERAGE(X4:AD4) -> 0 | AI4: =AVERAGE(C4:W4) -> 0
A5: 2 | B5: ='1.HAFTA'!B5 -> Ahmet Arif Ozmen | C5: i | D5: i | E5: i | F5: i | G5: i | H5: i | I5: i | Q5: i | R5: i | S5: i | T5: 1 | U5: i | V5: i | W5: i | X5: i | Y5: i | Z5: i | AA5: 1 | AB5: i | AC5: i | AD5: i | AE5: =AVERAGE(C5:I5) -> #DIV/0! | AF5: =AVERAGE(J5:P5) -> #DIV/0! | AG5: =AVERAGE(Q5:W5) -> 1 | AH5: =AVERAGE(X5:AD5) -> 1 | AI5: =AVERAGE(C5:W5) -> 1
A6: 3 | B6: ='1.HAFTA'!B6 -> Alihan Uysal | C6: i | D6: 0 | E6: 0 | F6: 0 | G6: 0 | H6: i | I6: i | Q6: 1 | R6: i | S6: i | T6: 1 | U6: i | V6: i | W6: i | X6: i | Y6: i | Z6: i | AA6: 1 | AB6: i | AC6: i | AD6: i | AE6: =AVERAGE(C6:I6) -> 0 | AF6: =AVERAGE(J6:P6) -> #DIV/0! | AG6: =AVERAGE(Q6:W6) -> 1 | AH6: =AVERAGE(X6:AD6) -> 1 | AI6: =AVERAGE(C6:W6) -> 0.33333333 | AK6: 45726 | AL6: 45732
A7: 4 | B7: ='1.HAFTA'!B7 -> Ammaar Ahmad | C7: i | D7: 1 | E7: 1 | F7: 1 | G7: 1 | H7: i | I7: i | Q7: 1 | R7: i | S7: i | T7: 1 | U7: 1 | V7: i | W7: i | X7: i | Y7: i | Z7: i | AA7: 1 | AB7: i | AC7: i | AD7: i | AE7: =AVERAGE(C7:I7) -> 1 | AF7: =AVERAGE(J7:P7) -> #DIV/0! | AG7: =AVERAGE(Q7:W7) -> 1 | AH7: =AVERAGE(X7:AD7) -> 1 | AI7: =AVERAGE(C7:W7) -> 1
A8: 5 | B8: ='1.HAFTA'!B8 -> Ekrem Altıntaş | C8: i | D8: 1 | E8: 0 | F8: 0 | G8: 0 | H8: i | I8: i | Q8: 1 | R8: i | S8: i | T8: 0 | U8: 1 | V8: i | W8: i | X8: i | Y8: i | Z8: i | AA8: 0 | AB8: i | AC8: i | AD8: i | AE8: =AVERAGE(C8:I8) -> 0.25 | AF8: =AVERAGE(J8:P8) -> #DIV/0! | AG8: =AVERAGE(Q8:W8) -> 0.66666667 | AH8: =AVERAGE(X8:AD8) -> 0 | AI8: =AVERAGE(C8:W8) -> 0.42857143
A9: 6 | B9: ='1.HAFTA'!B9 -> Emirhan Sak | C9: i | D9: 0 | E9: 1 | F9: 1 | G9: 1 | H9: i | I9: i | Q9: 1 | R9: i | S9: i | T9: 1 | U9: i | V9: i | W9: i | X9: i | Y9: i | Z9: i | AA9: 1 | AB9: i | AC9: i | AD9: i | AE9: =AVERAGE(C9:I9) -> 0.75 | AF9: =AVERAGE(J9:P9) -> #DIV/0! | AG9: =AVERAGE(Q9:W9) -> 1 | AH9: =AVERAGE(X9:AD9) -> 1 | AI9: =AVERAGE(C9:W9) -> 0.83333333
A10: 7 | B10: ='1.HAFTA'!B10 -> Eymen Göğebakan | C10: i | D10: 0 | E10: 1 | F10: 1 | G10: 1 | H10: i | I10: i | Q10: 1 | R10: i | S10: i | T10: 0 | U10: i | V10: i | W10: i | X10: i | Y10: i | Z10: i | AA10: 0 | AB10: i | AC10: i | AD10: i | AE10: =AVERAGE(C10:I10) -> 0.75 | AF10: =AVERAGE(J10:P10) -> #DIV/0! | AG10: =AVERAGE(Q10:W10) -> 0.5 | AH10: =AVERAGE(X10:AD10) -> 0 | AI10: =AVERAGE(C10:W10) -> 0.66666667
A11: 8 | B11: ='1.HAFTA'!B11 -> Mehmet Sak | C11: i | D11: 1 | E11: 1 | F11: 1 | G11: 1 | H11: i | I11: i | Q11: 1 | R11: i | S11: i | T11: 1 | U11: i | V11: i | W11: i | X11: i | Y11: i | Z11: i | AA11: 1 | AB11: i | AC11: i | AD11: i | AE11: =AVERAGE(C11:I11) -> 1 | AF11: =AVERAGE(J11:P11) -> #DIV/0! | AG11: =AVERAGE(Q11:W11) -> 1 | AH11: =AVERAGE(X11:AD11) -> 1 | AI11: =AVERAGE(C11:W11) -> 1
A12: 9 | B12: ='1.HAFTA'!B12 -> Mohammed Abdi Hakim | C12: i | D12: 1 | E12: 1 | F12: 1 | G12: 1 | H12: i | I12: i | Q12: 1 | R12: i | S12: i | T12: 1 | U12: 1 | V12: i | W12: i | X12: i | Y12: i | Z12: i | AA12: 1 | AB12: i | AC12: i | AD12: i | AE12: =AVERAGE(C12:I12) -> 1 | AF12: =AVERAGE(J12:P12) -> #DIV/0! | AG12: =AVERAGE(Q12:W12) -> 1 | AH12: =AVERAGE(X12:AD12) -> 1 | AI12: =AVERAGE(C12:W12) -> 1
A13: 10 | B13: ='1.HAFTA'!B13 -> Rıdvan Sönmez | C13: i | D13: 1 | E13: 1 | F13: 1 | G13: 1 | H13: i | I13: i | Q13: 1 | R13: i | S13: i | T13: 1 | U13: i | V13: i | W13: i | X13: i | Y13: i | Z13: i | AA13: 1 | AB13: i | AC13: i | AD13: i | AE13: =AVERAGE(C13:I13) -> 1 | AF13: =AVERAGE(J13:P13) -> #DIV/0! | AG13: =AVERAGE(Q13:W13) -> 1 | AH13: =AVERAGE(X13:AD13) -> 1 | AI13: =AVERAGE(C13:W13) -> 1
A14: 11 | B14: ='1.HAFTA'!B14 -> Tayyip Sönmez | C14: i | D14: i | E14: i | F14: i | G14: i | H14: i | I14: i | Q14: 1 | R14: i | S14: i | T14: i | U14: i | V14: i | W14: i | X14: i | Y14: i | Z14: i | AA14: i | AB14: i | AC14: i | AD14: i | AE14: =AVERAGE(C14:I14) -> #DIV/0! | AF14: =AVERAGE(J14:P14) -> #DIV/0! | AG14: =AVERAGE(Q14:W14) -> 1 | AH14: =AVERAGE(X14:AD14) -> #DIV/0! | AI14: =AVERAGE(C14:W14) -> 1
A15: 12 | B15: ='1.HAFTA'!B15 -> Waffi Talib | C15: i | D15: i | E15: i | F15: 1 | G15: 1 | H15: i | I15: i | Q15: i | R15: i | S15: i | T15: 1 | U15: 0 | V15: i | W15: i | X15: i | Y15: i | Z15: i | AA15: 1 | AB15: i | AC15: i | AD15: i | AE15: =AVERAGE(C15:I15) -> 1 | AF15: =AVERAGE(J15:P15) -> #DIV/0! | AG15: =AVERAGE(Q15:W15) -> 0.5 | AH15: =AVERAGE(X15:AD15) -> 1 | AI15: =AVERAGE(C15:W15) -> 0.75
A16: 13 | B16: ='1.HAFTA'!B16 -> Ahmet Enes Küçüktepe | C16: i | D16: 0 | E16: 0 | F16: 0 | G16: 1 | H16: i | I16: i | Q16: 1 | R16: i | S16: i | T16: I | U16: i | V16: i | W16: i | X16: i | Y16: i | Z16: i | AA16: I | AB16: i | AC16: i | AD16: i | AE16: =AVERAGE(C16:I16) -> 0.25 | AF16: =AVERAGE(J16:P16) -> #DIV/0! | AG16: =AVERAGE(Q16:W16) -> 1 | AH16: =AVERAGE(X16:AD16) -> #DIV/0! | AI16: =AVERAGE(C16:W16) -> 0.4
A17: 14 | B17: ='1.HAFTA'!B17 -> Abdulkerim Karazehir | C17: i | D17: i | E17: i | F17: 0 | G17: 1 | H17: i | I17: i | Q17: i | R17: i | S17: i | T17: 0 | U17: 0 | V17: i | W17: i | X17: i | Y17: i | Z17: i | AA17: 0 | AB17: i | AC17: i | AD17: i | AE17: =AVERAGE(C17:I17) -> 0.5 | AF17: =AVERAGE(J17:P17) -> #DIV/0! | AG17: =AVERAGE(Q17:W17) -> 0 | AH17: =AVERAGE(X17:AD17) -> 0 | AI17: =AVERAGE(C17:W17) -> 0.25
A18: 15 | B18: ='1.HAFTA'!B18 -> Berat Basan | C18: i | D18: 0 | E18: 0 | F18: 0 | G18: 1 | H18: i | I18: i | Q18: i | R18: i | S18: i | T18: 0 | U18: 0 | V18: i | W18: i | X18: i | Y18: i | Z18: i | AA18: 0 | AB18: i | AC18: i | AD18: i | AE18: =AVERAGE(C18:I18) -> 0.25 | AF18: =AVERAGE(J18:P18) -> #DIV/0! | AG18: =AVERAGE(Q18:W18) -> 0 | AH18: =AVERAGE(X18:AD18) -> 0 | AI18: =AVERAGE(C18:W18) -> 0.16666667
A19: 16 | B19: ='1.HAFTA'!B19 -> Burhan Çevik | C19: i | D19: 0 | E19: 0 | F19: 0 | G19: 1 | H19: i | I19: i | Q19: 0 | R19: i | S19: i | T19: 0 | U19: 0 | V19: i | W19: i | X19: i | Y19: i | Z19: i | AA19: 0 | AB19: i | AC19: i | AD19: i | AE19: =AVERAGE(C19:I19) -> 0.25 | AF19: =AVERAGE(J19:P19) -> #DIV/0! | AG19: =AVERAGE(Q19:W19) -> 0 | AH19: =AVERAGE(X19:AD19) -> 0 | AI19: =AVERAGE(C19:W19) -> 0.14285714
A20: 17 | B20: ='1.HAFTA'!B20 -> Enes Bakar | C20: i | D20: 0 | E20: 0 | F20: 0 | G20: 0 | H20: i | I20: i | Q20: 0 | R20: i | S20: i | T20: 0 | U20: 0 | V20: i | W20: i | X20: i | Y20: i | Z20: i | AA20: 0 | AB20: i | AC20: i | AD20: i | AE20: =AVERAGE(C20:I20) -> 0 | AF20: =AVERAGE(J20:P20) -> #DIV/0! | AG20: =AVERAGE(Q20:W20) -> 0 | AH20: =AVERAGE(X20:AD20) -> 0 | AI20: =AVERAGE(C20:W20) -> 0
A21: 18 | B21: ='1.HAFTA'!B21 -> Hüseyin Özdemir | C21: i | D21: 0 | E21: 1 | F21: 0 | G21: 1 | H21: i | I21: i | Q21: 1 | R21: i | S21: i | T21: 0 | U21: 0 | V21: i | W21: i | X21: i | Y21: i | Z21: i | AA21: 0 | AB21: i | AC21: i | AD21: i | AE21: =AVERAGE(C21:I21) -> 0.5 | AF21: =AVERAGE(J21:P21) -> #DIV/0! | AG21: =AVERAGE(Q21:W21) -> 0.33333333 | AH21: =AVERAGE(X21:AD21) -> 0 | AI21: =AVERAGE(C21:W21) -> 0.42857143
A22: 19 | B22: ='1.HAFTA'!B22 -> Yahya Yıldız | C22: i | D22: 0 | E22: 1 | F22: 0 | G22: 1 | H22: i | I22: i | Q22: 0 | R22: i | S22: i | T22: i | U22: 0 | V22: i | W22: i | X22: i | Y22: i | Z22: i | AA22: i | AB22: i | AC22: i | AD22: i | AE22: =AVERAGE(C22:I22) -> 0.5 | AF22: =AVERAGE(J22:P22) -> #DIV/0! | AG22: =AVERAGE(Q22:W22) -> 0 | AH22: =AVERAGE(X22:AD22) -> #DIV/0! | AI22: =AVERAGE(C22:W22) -> 0.33333333
A23: 20 | B23: ='1.HAFTA'!B23 -> Yakup Karazehir | C23: i | D23: 1 | E23: 1 | F23: 1 | G23: 1 | H23: i | I23: i | Q23: 1 | R23: i | S23: i | T23: 1 | U23: 1 | V23: i | W23: i | X23: i | Y23: i | Z23: i | AA23: 1 | AB23: i | AC23: i | AD23: i | AE23: =AVERAGE(C23:I23) -> 1 | AF23: =AVERAGE(J23:P23) -> #DIV/0! | AG23: =AVERAGE(Q23:W23) -> 1 | AH23: =AVERAGE(X23:AD23) -> 1 | AI23: =AVERAGE(C23:W23) -> 1
A24: 21 | B24: ='1.HAFTA'!B24 -> Abdussamed Arslan | C24: i | D24: 1 | E24: 0 | F24: 1 | G24: 0 | H24: i | I24: i | Q24: 0 | R24: i | S24: i | T24: 0 | U24: 0 | V24: i | W24: i | X24: i | Y24: i | Z24: i | AA24: 0 | AB24: i | AC24: i | AD24: i | AE24: =AVERAGE(C24:I24) -> 0.5 | AF24: =AVERAGE(J24:P24) -> #DIV/0! | AG24: =AVERAGE(Q24:W24) -> 0 | AH24: =AVERAGE(X24:AD24) -> 0 | AI24: =AVERAGE(C24:W24) -> 0.28571429
A25: 22 | B25: ='1.HAFTA'!B25 -> Abdussamed Erdem | C25: i | D25: 1 | E25: 1 | F25: 1 | G25: 1 | H25: i | I25: i | Q25: 1 | R25: i | S25: i | T25: 1 | U25: i | V25: i | W25: i | X25: i | Y25: i | Z25: i | AA25: 1 | AB25: i | AC25: i | AD25: i | AE25: =AVERAGE(C25:I25) -> 1 | AF25: =AVERAGE(J25:P25) -> #DIV/0! | AG25: =AVERAGE(Q25:W25) -> 1 | AH25: =AVERAGE(X25:AD25) -> 1 | AI25: =AVERAGE(C25:W25) -> 1
A26: 23 | B26: ='1.HAFTA'!B26 -> Ahmet Boyacıoğlu | C26: i | D26: 1 | E26: 1 | F26: 1 | G26: 1 | H26: i | I26: i | Q26: 0 | R26: i | S26: i | T26: 0 | U26: 0 | V26: i | W26: i | X26: i | Y26: i | Z26: i | AA26: 0 | AB26: i | AC26: i | AD26: i | AE26: =AVERAGE(C26:I26) -> 1 | AF26: =AVERAGE(J26:P26) -> #DIV/0! | AG26: =AVERAGE(Q26:W26) -> 0 | AH26: =AVERAGE(X26:AD26) -> 0 | AI26: =AVERAGE(C26:W26) -> 0.57142857
A27: 24 | B27: ='1.HAFTA'!B27 -> Ahmet Kökçü | C27: i | D27: 1 | E27: 1 | F27: 1 | G27: 1 | H27: i | I27: i | Q27: 1 | R27: i | S27: i | T27: 1 | U27: 1 | V27: i | W27: i | X27: i | Y27: i | Z27: i | AA27: 1 | AB27: i | AC27: i | AD27: i | AE27: =AVERAGE(C27:I27) -> 1 | AF27: =AVERAGE(J27:P27) -> #DIV/0! | AG27: =AVERAGE(Q27:W27) -> 1 | AH27: =AVERAGE(X27:AD27) -> 1 | AI27: =AVERAGE(C27:W27) -> 1
A28: 25 | B28: ='1.HAFTA'!B28 -> Fatih Burcu | C28: i | D28: 1 | E28: 1 | F28: 1 | G28: 1 | H28: i | I28: i | Q28: 1 | R28: i | S28: i | T28: 1 | U28: 1 | V28: i | W28: i | X28: i | Y28: i | Z28: i | AA28: 1 | AB28: i | AC28: i | AD28: i | AE28: =AVERAGE(C28:I28) -> 1 | AF28: =AVERAGE(J28:P28) -> #DIV/0! | AG28: =AVERAGE(Q28:W28) -> 1 | AH28: =AVERAGE(X28:AD28) -> 1 | AI28: =AVERAGE(C28:W28) -> 1
A29: 26 | B29: ='1.HAFTA'!B29 -> Fehmi Kütük | C29: i | D29: 1 | E29: 1 | F29: 1 | G29: 1 | H29: i | I29: i | Q29: 0 | R29: i | S29: i | T29: s | U29: 0 | V29: i | W29: i | X29: i | Y29: i | Z29: i | AA29: s | AB29: i | AC29: i | AD29: i | AE29: =AVERAGE(C29:I29) -> 1 | AF29: =AVERAGE(J29:P29) -> #DIV/0! | AG29: =AVERAGE(Q29:W29) -> 0 | AH29: =AVERAGE(X29:AD29) -> #DIV/0! | AI29: =AVERAGE(C29:W29) -> 0.66666667
A30: 27 | B30: ='1.HAFTA'!B30 -> Mehmet Cakmak | C30: i | D30: 1 | E30: 1 | F30: 1 | G30: 1 | H30: i | I30: i | Q30: 1 | R30: i | S30: i | T30: 1 | U30: 1 | V30: i | W30: i | X30: i | Y30: i | Z30: i | AA30: 1 | AB30: i | AC30: i | AD30: i | AE30: =AVERAGE(C30:I30) -> 1 | AF30: =AVERAGE(J30:P30) -> #DIV/0! | AG30: =AVERAGE(Q30:W30) -> 1 | AH30: =AVERAGE(X30:AD30) -> 1 | AI30: =AVERAGE(C30:W30) -> 1
A31: 28 | B31: ='1.HAFTA'!B31 -> Rasit Aldirmaz | C31: i | D31: i | E31: i | F31: 1 | G31: 1 | H31: i | I31: i | Q31: i | R31: i | S31: i | T31: 1 | U31: 0 | V31: i | W31: i | X31: i | Y31: i | Z31: i | AA31: 1 | AB31: i | AC31: i | AD31: i | AE31: =AVERAGE(C31:I31) -> 1 | AF31: =AVERAGE(J31:P31) -> #DIV/0! | AG31: =AVERAGE(Q31:W31) -> 0.5 | AH31: =AVERAGE(X31:AD31) -> 1 | AI31: =AVERAGE(C31:W31) -> 0.75
A32: 29 | B32: ='1.HAFTA'!B32 -> Tunahan Altun | C32: i | D32: 1 | E32: 1 | F32: 1 | G32: 1 | H32: i | I32: i | Q32: 0 | R32: i | S32: i | T32: 1 | U32: i | V32: i | W32: i | X32: i | Y32: i | Z32: i | AA32: 1 | AB32: i | AC32: i | AD32: i | AE32: =AVERAGE(C32:I32) -> 1 | AF32: =AVERAGE(J32:P32) -> #DIV/0! | AG32: =AVERAGE(Q32:W32) -> 0.5 | AH32: =AVERAGE(X32:AD32) -> 1 | AI32: =AVERAGE(C32:W32) -> 0.83333333
A33: 30 | B33: ='1.HAFTA'!B33 -> Yusuf Emin Doğan | C33: i | D33: 1 | E33: 1 | F33: 1 | G33: 1 | H33: i | I33: i | Q33: 0 | R33: i | S33: i | T33: o | U33: 0 | V33: i | W33: i | X33: i | Y33: i | Z33: i | AA33: o | AB33: i | AC33: i | AD33: i | AE33: =AVERAGE(C33:I33) -> 1 | AF33: =AVERAGE(J33:P33) -> #DIV/0! | AG33: =AVERAGE(Q33:W33) -> 0 | AH33: =AVERAGE(X33:AD33) -> #DIV/0! | AI33: =AVERAGE(C33:W33) -> 0.66666667
A34: 31 | B34: ='1.HAFTA'!B34 -> Ahmet Doğan | C34: i | D34: 1 | E34: 1 | F34: 1 | G34: 1 | H34: i | I34: i | Q34: 1 | R34: i | S34: i | T34: 0 | U34: 1 | V34: i | W34: i | X34: i | Y34: i | Z34: i | AA34: 0 | AB34: i | AC34: i | AD34: i | AE34: =AVERAGE(C34:I34) -> 1 | AF34: =AVERAGE(J34:P34) -> #DIV/0! | AG34: =AVERAGE(Q34:W34) -> 0.66666667 | AH34: =AVERAGE(X34:AD34) -> 0 | AI34: =AVERAGE(C34:W34) -> 0.85714286
A35: 32 | B35: ='1.HAFTA'!B35 -> Cihan Boorsma | C35: i | D35: 0 | E35: 1 | F35: 1 | G35: 1 | H35: i | I35: i | Q35: 1 | R35: i | S35: i | T35: 1 | U35: 1 | V35: i | W35: i | X35: i | Y35: i | Z35: i | AA35: 1 | AB35: i | AC35: i | AD35: i | AE35: =AVERAGE(C35:I35) -> 0.75 | AF35: =AVERAGE(J35:P35) -> #DIV/0! | AG35: =AVERAGE(Q35:W35) -> 1 | AH35: =AVERAGE(X35:AD35) -> 1 | AI35: =AVERAGE(C35:W35) -> 0.85714286
A36: 33 | B36: ='1.HAFTA'!B36 -> Mehmethan Gür | C36: i | D36: 1 | E36: 1 | F36: 1 | G36: 1 | H36: i | I36: i | Q36: 1 | R36: i | S36: i | T36: 1 | U36: 1 | V36: i | W36: i | X36: i | Y36: i | Z36: i | AA36: 1 | AB36: i | AC36: i | AD36: i | AE36: =AVERAGE(C36:I36) -> 1 | AF36: =AVERAGE(J36:P36) -> #DIV/0! | AG36: =AVERAGE(Q36:W36) -> 1 | AH36: =AVERAGE(X36:AD36) -> 1 | AI36: =AVERAGE(C36:W36) -> 1
A37: 34 | B37: ='1.HAFTA'!B37 -> Melih Taş | C37: i | D37: 1 | E37: 1 | F37: 1 | G37: 1 | H37: i | I37: i | Q37: 0 | R37: i | S37: i | T37: 0 | U37: 0 | V37: i | W37: i | X37: i | Y37: i | Z37: i | AA37: 0 | AB37: i | AC37: i | AD37: i | AE37: =AVERAGE(C37:I37) -> 1 | AF37: =AVERAGE(J37:P37) -> #DIV/0! | AG37: =AVERAGE(Q37:W37) -> 0 | AH37: =AVERAGE(X37:AD37) -> 0 | AI37: =AVERAGE(C37:W37) -> 0.57142857
A38: 35 | B38: ='1.HAFTA'!B38 -> Melih Uzun | C38: i | D38: y | E38: 1 | F38: 1 | G38: 1 | H38: i | I38: i | Q38: 0 | R38: i | S38: i | T38: 1 | U38: 1 | V38: i | W38: i | X38: i | Y38: i | Z38: i | AA38: 1 | AB38: i | AC38: i | AD38: i | AE38: =AVERAGE(C38:I38) -> 1 | AF38: =AVERAGE(J38:P38) -> #DIV/0! | AG38: =AVERAGE(Q38:W38) -> 0.66666667 | AH38: =AVERAGE(X38:AD38) -> 1 | AI38: =AVERAGE(C38:W38) -> 0.83333333
A39: 36 | B39: ='1.HAFTA'!B39 -> Mucahit Kan | C39: i | D39: 1 | E39: 0 | F39: 0 | G39: 1 | H39: i | I39: i | Q39: 0 | R39: i | S39: i | T39: 1 | U39: 0 | V39: i | W39: i | X39: i | Y39: i | Z39: i | AA39: 1 | AB39: i | AC39: i | AD39: i | AE39: =AVERAGE(C39:I39) -> 0.5 | AF39: =AVERAGE(J39:P39) -> #DIV/0! | AG39: =AVERAGE(Q39:W39) -> 0.33333333 | AH39: =AVERAGE(X39:AD39) -> 1 | AI39: =AVERAGE(C39:W39) -> 0.42857143
A40: 37 | B40: ='1.HAFTA'!B40 -> Oğuzhan Üzümcü | C40: i | D40: 1 | E40: 1 | F40: 1 | G40: 1 | H40: i | I40: i | Q40: 1 | R40: i | S40: i | T40: 1 | U40: 1 | V40: i | W40: i | X40: i | Y40: i | Z40: i | AA40: 1 | AB40: i | AC40: i | AD40: i | AE40: =AVERAGE(C40:I40) -> 1 | AF40: =AVERAGE(J40:P40) -> #DIV/0! | AG40: =AVERAGE(Q40:W40) -> 1 | AH40: =AVERAGE(X40:AD40) -> 1 | AI40: =AVERAGE(C40:W40) -> 1
...

Sheet 3.HAFTA
A1: =('1.HAFTA'!A1:AD1) -> TALEBE TAKİP SİSTEMİ 2024-2025 | AE1: =('1.HAFTA'!AE1:AI1) -> Amsterdam Saray
A2: 3.HAFTA | C2: SABAH NAMAZI PROGRAMLARI | J2: AKŞAM NAMAZI PROĞRAMLARI | Q2: YATSI NAMAZI PROGRAMLARI | X2: HATİM | AE2: 3.HAFTA ORTALAMALAR
A3: NO | B3: ADI SOYADI | C3: PAZARTESİ | D3: SALI | E3: ÇARŞAMBA | F3: PERŞEMBE | G3: CUMA | H3: CUMARTESİ | I3: PAZAR | J3: PAZARTESİ | K3: SALI | L3: ÇARŞAMBA | M3: PERŞEMBE | N3: CUMA | O3: CUMARTESİ | P3: PAZAR | Q3: PAZARTESİ | R3: SALI | S3: ÇARŞAMBA | T3: PERŞEMBE | U3: CUMA | V3: CUMARTESİ | W3: PAZAR | X3: PAZARTESİ | Y3: SALI | Z3: ÇARŞAMBA | AA3: PERŞEMBE | AB3: CUMA | AC3: CUMARTESİ | AD3: PAZAR | AE3: SABAH | AF3: AKŞAM | AG3: YATSI | AH3: HATİM | AI3: NAMAZ
A4: 1 | B4: ='1.HAFTA'!B4 -> Abdullah Koşar | C4: i | D4: 0 | E4: i | F4: i | G4: 0 | H4: i | I4: i | Q4: 0 | R4: 0 | S4: 0 | T4: 0 | U4: i | V4: i | W4: i | X4: i | Y4: i | Z4: 0 | AA4: 0 | AB4: i | AC4: i | AD4: i | AE4: =AVERAGE(C4:I4) -> 0 | AF4: =AVERAGE(J4:P4) -> #DIV/0! | AG4: =AVERAGE(Q4:W4) -> 0 | AH4: =AVERAGE(X4:AD4) -> 0 | AI4: =AVERAGE(C4:W4) -> 0
A5: 2 | B5: ='1.HAFTA'!B5 -> Ahmet Arif Ozmen | C5: i | D5: i | E5: i | F5: i | G5: i | H5: i | I5: i | Q5: i | R5: 1 | S5: i | T5: 1 | U5: i | V5: i | W5: i | X5: i | Y5: i | Z5: i | AA5: 1 | AB5: i | AC5: i | AD5: i | AE5: =AVERAGE(C5:I5) -> #DIV/0! | AF5: =AVERAGE(J5:P5) -> #DIV/0! | AG5: =AVERAGE(Q5:W5) -> 1 | AH5: =AVERAGE(X5:AD5) -> 1 | AI5: =AVERAGE(C5:W5) -> 1 | AL5: 45733 | AM5: 45739
A6: 3 | B6: ='1.HAFTA'!B6 -> Alihan Uysal | C6: i | D6: 0 | E6: i | F6: i | G6: b | H6: i | I6: i | Q6: 0 | R6: 0 | S6: 0 | T6: 1 | U6: i | V6: i | W6: i | X6: i | Y6: i | Z6: 0 | AA6: 1 | AB6: i | AC6: i | AD6: i | AE6: =AVERAGE(C6:I6) -> 0 | AF6: =AVERAGE(J6:P6) -> #DIV/0! | AG6: =AVERAGE(Q6:W6) -> 0.25 | AH6: =AVERAGE(X6:AD6) -> 0.5 | AI6: =AVERAGE(C6:W6) -> 0.2
A7: 4 | B7: ='1.HAFTA'!B7 -> Ammaar Ahmad | C7: i | D7: 1 | E7: 1 | F7: i | G7: 1 | H7: i | I7: i | Q7: 1 | R7: 1 | S7: 1 | T7: 1 | U7: i | V7: i | W7: i | X7: i | Y7: i | Z7: 1 | AA7: 1 | AB7: i | AC7: i | AD7: i | AE7: =AVERAGE(C7:I7) -> 1 | AF7: =AVERAGE(J7:P7) -> #DIV/0! | AG7: =AVERAGE(Q7:W7) -> 1 | AH7: =AVERAGE(X7:AD7) -> 1 | AI7: =AVERAGE(C7:W7) -> 1
A8: 5 | B8: ='1.HAFTA'!B8 -> Ekrem Altıntaş | C8: i | D8: 0 | E8: i | F8: i | G8: 0 | H8: i | I8: i | Q8: 1 | R8: 0 | S8: 0 | T8: 1 | U8: i | V8: i | W8: i | X8: i | Y8: i | Z8: 0 | AA8: 1 | AB8: i | AC8: i | AD8: i | AE8: =AVERAGE(C8:I8) -> 0 | AF8: =AVERAGE(J8:P8) -> #DIV/0! | AG8: =AVERAGE(Q8:W8) -> 0.5 | AH8: =AVERAGE(X8:AD8) -> 0.5 | AI8: =AVERAGE(C8:W8) -> 0.33333333
A9: 6 | B9: ='1.HAFTA'!B9 -> Emirhan Sak | C9: i | D9: i | E9: i | F9: i | G9: 0 | H9: i | I9: i | Q9: i | R9: 1 | S9: 1 | T9: 1 | U9: i | V9: i | W9: i | X9: i | Y9: i | Z9: 1 | AA9: 1 | AB9: i | AC9: i | AD9: i | AE9: =AVERAGE(C9:I9) -> 0 | AF9: =AVERAGE(J9:P9) -> #DIV/0! | AG9: =AVERAGE(Q9:W9) -> 1 | AH9: =AVERAGE(X9:AD9) -> 1 | AI9: =AVERAGE(C9:W9) -> 0.75
A10: 7 | B10: ='1.HAFTA'!B10 -> Eymen Göğebakan | C10: i | D10: 1 | E10: 1 | F10: i | G10: 1 | H10: i | I10: i | Q10: 0 | R10: 1 | S10: 1 | T10: 1 | U10: i | V10: i | W10: i | X10: i | Y10: i | Z10: 1 | AA10: 1 | AB10: i | AC10: i | AD10: i | AE10: =AVERAGE(C10:I10) -> 1 | AF10: =AVERAGE(J10:P10) -> #DIV/0! | AG10: =AVERAGE(Q10:W10) -> 0.75 | AH10: =AVERAGE(X10:AD10) -> 1 | AI10: =AVERAGE(C10:W10) -> 0.85714286
A11: 8 | B11: ='1.HAFTA'!B11 -> Mehmet Sak | C11: i | D11: 1 | E11: 1 | F11: i | G11: 1 | H11: i | I11: i | Q11: 1 | R11: 1 | S11: 1 | T11: 1 | U11: i | V11: i | W11: i | X11: i | Y11: i | Z11: 1 | AA11: 1 | AB11: i | AC11: i | AD11: i | AE11: =AVERAGE(C11:I11) -> 1 | AF11: =AVERAGE(J11:P11) -> #DIV/0! | AG11: =AVERAGE(Q11:W11) -> 1 | AH11: =AVERAGE(X11:AD11) -> 1 | AI11: =AVERAGE(C11:W11) -> 1
A12: 9 | B12: ='1.HAFTA'!B12 -> Mohammed Abdi Hakim | C12: i | D12: 1 | E12: i | F12: i | G12: 1 | H12: i | I12: i | Q12: 1 | R12: 0 | S12: 0 | T12: 0 | U12: i | V12: i | W12: i | X12: i | Y12: i | Z12: 1 | AA12: 1 | AB12: i | AC12: i | AD12: i | AE12: =AVERAGE(C12:I12) -> 1 | AF12: =AVERAGE(J12:P12) -> #DIV/0! | AG12: =AVERAGE(Q12:W12) -> 0.25 | AH12: =AVERAGE(X12:AD12) -> 1 | AI12: =AVERAGE(C12:W12) -> 0.5
A13: 10 | B13: ='1.HAFTA'!B13 -> Rıdvan Sönmez | C13: i | D13: 1 | E13: 1 | F13: i | G13: i | H13: i | I13: i | Q13: 1 | R13: 1 | S13: 1 | T13: i | U13: i | V13: i | W13: i | X13: i | Y13: i | Z13: 1 | AA13: i | AB13: i | AC13: i | AD13: i | AE13: =AVERAGE(C13:I13) -> 1 | AF13: =AVERAGE(J13:P13) -> #DIV/0! | AG13: =AVERAGE(Q13:W13) -> 1 | AH13: =AVERAGE(X13:AD13) -> 1 | AI13: =AVERAGE(C13:W13) -> 1
A14: 11 | B14: ='1.HAFTA'!B14 -> Tayyip Sönmez | C14: i | D14: i | E14: i | F14: i | G14: i | H14: i | I14: i | Q14: i | R14: i | S14: i | T14: i | U14: i | V14: i | W14: i | X14: i | Y14: i | Z14: i | AA14: i | AB14: i | AC14: i | AD14: i | AE14: =AVERAGE(C14:I14) -> #DIV/0! | AF14: =AVERAGE(J14:P14) -> #DIV/0! | AG14: =AVERAGE(Q14:W14) -> #DIV/0! | AH14: =AVERAGE(X14:AD14) -> #DIV/0! | AI14: =AVERAGE(C14:W14) -> #DIV/0!
A15: 12 | B15: ='1.HAFTA'!B15 -> Waffi Talib | C15: i | D15: i | E15: i | F15: i | G15: 1 | H15: i | I15: i | Q15: i | R15: i | S15: 0 | T15: i | U15: i | V15: i | W15: i | X15: i | Y15: i | Z15: 1 | AA15: i | AB15: i | AC15: i | AD15: i | AE15: =AVERAGE(C15:I15) -> 1 | AF15: =AVERAGE(J15:P15) -> #DIV/0! | AG15: =AVERAGE(Q15:W15) -> 0 | AH15: =AVERAGE(X15:AD15) -> 1 | AI15: =AVERAGE(C15:W15) -> 0.5
A16: 13 | B16: ='1.HAFTA'!B16 -> Ahmet Enes Küçüktepe | C16: i | D16: 1 | E16: i | F16: i | G16: 1 | H16: i | I16: i | Q16: i | R16: i | S16: 0 | T16: I | U16: i | V16: i | W16: i | X16: i | Y16: i | Z16: 0 | AA16: I | AB16: i | AC16: i | AD16: i | AE16: =AVERAGE(C16:I16) -> 1 | AF16: =AVERAGE(J16:P16) -> #DIV/0! | AG16: =AVERAGE(Q16:W16) -> 0 | AH16: =AVERAGE(X16:AD16) -> 0 | AI16: =AVERAGE(C16:W16) -> 0.66666667
A17: 14 | B17: ='1.HAFTA'!B17 -> Abdulkerim Karazehir | C17: i | D17: 1 | E17: 1 | F17: i | G17: 1 | H17: i | I17: i | Q17: 0 | R17: o | S17: 0 | T17: 0 | U17: i | V17: i | W17: i | X17: i | Y17: i | Z17: 1 | AA17: 1 | AB17: i | AC17: i | AD17: i | AE17: =AVERAGE(C17:I17) -> 1 | AF17: =AVERAGE(J17:P17) -> #DIV/0! | AG17: =AVERAGE(Q17:W17) -> 0 | AH17: =AVERAGE(X17:AD17) -> 1 | AI17: =AVERAGE(C17:W17) -> 0.5
A18: 15 | B18: ='1.HAFTA'!B18 -> Berat Basan | C18: i | D18: 0 | E18: i | F18: i | G18: 1 | H18: i | I18: i | Q18: 0 | R18: 0 | S18: 0 | T18: 0 | U18: i | V18: i | W18: i | X18: i | Y18: i | Z18: 1 | AA18: 1 | AB18: i | AC18: i | AD18: i | AE18: =AVERAGE(C18:I18) -> 0.5 | AF18: =AVERAGE(J18:P18) -> #DIV/0! | AG18: =AVERAGE(Q18:W18) -> 0 | AH18: =AVERAGE(X18:AD18) -> 1 | AI18: =AVERAGE(C18:W18) -> 0.16666667
A19: 16 | B19: ='1.HAFTA'!B19 -> Burhan Çevik | C19: i | D19: 1 | E19: i | F19: i | G19: 1 | H19: i | I19: i | Q19: 0 | R19: 1 | S19: 1 | T19: 0 | U19: i | V19: i | W19: i | X19: i | Y19: i | Z19: 1 | AA19: 1 | AB19: i | AC19: i | AD19: i | AE19: =AVERAGE(C19:I19) -> 1 | AF19: =AVERAGE(J19:P19) -> #DIV/0! | AG19: =AVERAGE(Q19:W19) -> 0.5 | AH19: =AVERAGE(X19:AD19) -> 1 | AI19: =AVERAGE(C19:W19) -> 0.66666667
A20: 17 | B20: ='1.HAFTA'!B20 -> Enes Bakar | C20: i | D20: 0 | E20: i | F20: i | G20: y | H20: i | I20: i | Q20: 0 | R20: 0 | S20: 0 | T20: 0 | U20: i | V20: i | W20: i | X20: i | Y20: i | Z20: 0 | AA20: 1 | AB20: i | AC20: i | AD20: i | AE20: =AVERAGE(C20:I20) -> 0 | AF20: =AVERAGE(J20:P20) -> #DIV/0! | AG20: =AVERAGE(Q20:W20) -> 0 | AH20: =AVERAGE(X20:AD20) -> 0.5 | AI20: =AVERAGE(C20:W20) -> 0
A21: 18 | B21: ='1.HAFTA'!B21 -> Hüseyin Özdemir | C21: i | D21: 0 | E21: i | F21: i | G21: 1 | H21: i | I21: i | Q21: 0 | R21: 1 | S21: 0 | T21: 1 | U21: i | V21: i | W21: i | X21: i | Y21: i | Z21: 0 | AA21: 1 | AB21: i | AC21: i | AD21: i | AE21: =AVERAGE(C21:I21) -> 0.5 | AF21: =AVERAGE(J21:P21) -> #DIV/0! | AG21: =AVERAGE(Q21:W21) -> 0.5 | AH21: =AVERAGE(X21:AD21) -> 0.5 | AI21: =AVERAGE(C21:W21) -> 0.5
A22: 19 | B22: ='1.HAFTA'!B22 -> Yahya Yıldız | C22: i | D22: 0 | E22: 1 | F22: i | G22: i | H22: i | I22: i | Q22: 0 | R22: 1 | S22: i | T22: 0 | U22: i | V22: i | W22: i | X22: i | Y22: i | Z22: i | AA22: 0 | AB22: i | AC22: i | AD22: i | AE22: =AVERAGE(C22:I22) -> 0.5 | AF22: =AVERAGE(J22:P22) -> #DIV/0! | AG22: =AVERAGE(Q22:W22) -> 0.33333333 | AH22: =AVERAGE(X22:AD22) -> 0 | AI22: =AVERAGE(C22:W22) -> 0.4
A23: 20 | B23: ='1.HAFTA'!B23 -> Yakup Karazehir | C23: i | D23: 1 | E23: 1 | F23: i | G23: 1 | H23: i | I23: i | Q23: 1 | R23: 1 | S23: 1 | T23: 1 | U23: i | V23: i | W23: i | X23: i | Y23: i | Z23: 1 | AA23: 1 | AB23: i | AC23: i | AD23: i | AE23: =AVERAGE(C23:I23) -> 1 | AF23: =AVERAGE(J23:P23) -> #DIV/0! | AG23: =AVERAGE(Q23:W23) -> 1 | AH23: =AVERAGE(X23:AD23) -> 1 | AI23: =AVERAGE(C23:W23) -> 1
A24: 21 | B24: ='1.HAFTA'!B24 -> Abdussamed Arslan | C24: i | D24: 0 | E24: i | F24: i | G24: 1 | H24: i | I24: i | Q24: 0 | R24: 0 | S24: 0 | T24: 0 | U24: i | V24: i | W24: i | X24: i | Y24: i | Z24: 0 | AA24: 1 | AB24: i | AC24: i | AD24: i | AE24: =AVERAGE(C24:I24) -> 0.5 | AF24: =AVERAGE(J24:P24) -> #DIV/0! | AG24: =AVERAGE(Q24:W24) -> 0 | AH24: =AVERAGE(X24:AD24) -> 0.5 | AI24: =AVERAGE(C24:W24) -> 0.16666667
A25: 22 | B25: ='1.HAFTA'!B25 -> Abdussamed Erdem | C25: i | D25: 1 | E25: i | F25: i | G25: 1 | H25: i | I25: i | Q25: 1 | R25: 1 | S25: 1 | T25: 1 | U25: i | V25: i | W25: i | X25: i | Y25: i | Z25: 1 | AA25: 1 | AB25: i | AC25: i | AD25: i | AE25: =AVERAGE(C25:I25) -> 1 | AF25: =AVERAGE(J25:P25) -> #DIV/0! | AG25: =AVERAGE(Q25:W25) -> 1 | AH25: =AVERAGE(X25:AD25) -> 1 | AI25: =AVERAGE(C25:W25) -> 1
A26: 23 | B26: ='1.HAFTA'!B26 -> Ahmet Boyacıoğlu | C26: i | D26: 1 | E26: i | F26: i | H26: i | I26: i | Q26: 0 | R26: 0 | S26: 0 | T26: 0 | U26: i | V26: i | W26: i | X26: i | Y26: i | Z26: 0 | AA26: 1 | AB26: i | AC26: i | AD26: i | AE26: =AVERAGE(C26:I26) -> 1 | AF26: =AVERAGE(J26:P26) -> #DIV/0! | AG26: =AVERAGE(Q26:W26) -> 0 | AH26: =AVERAGE(X26:AD26) -> 0.5 | AI26: =AVERAGE(C26:W26) -> 0.2
A27: 24 | B27: ='1.HAFTA'!B27 -> Ahmet Kökçü | C27: i | D27: i | E27: 1 | F27: i | G27: i | H27: i | I27: i | Q27: i | R27: 1 | S27: 1 | T27: i | U27: i | V27: i | W27: i | X27: i | Y27: i | Z27: 1 | AA27: i | AB27: i | AC27: i | AD27: i | AE27: =AVERAGE(C27:I27) -> 1 | AF27: =AVERAGE(J27:P27) -> #DIV/0! | AG27: =AVERAGE(Q27:W27) -> 1 | AH27: =AVERAGE(X27:AD27) -> 1 | AI27: =AVERAGE(C27:W27) -> 1
A28: 25 | B28: ='1.HAFTA'!B28 -> Fatih Burcu | C28: i | D28: 1 | E28: 1 | F28: i | G28: 1 | H28: i | I28: i | Q28: 1 | R28: 1 | S28: 1 | T28: 1 | U28: i | V28: i | W28: i | X28: i | Y28: i | Z28: 1 | AA28: 1 | AB28: i | AC28: i | AD28: i | AE28: =AVERAGE(C28:I28) -> 1 | AF28: =AVERAGE(J28:P28) -> #DIV/0! | AG28: =AVERAGE(Q28:W28) -> 1 | AH28: =AVERAGE(X28:AD28) -> 1 | AI28: =AVERAGE(C28:W28) -> 1
A29: 26 | B29: ='1.HAFTA'!B29 -> Fehmi Kütük | C29: i | D29: 1 | E29: 1 | F29: i | G29: 1 | H29: i | I29: i | Q29: 0 | R29: i | S29: 0 | T29: s | U29: i | V29: i | W29: i | X29: i | Y29: i | Z29: 1 | AA29: s | AB29: i | AC29: i | AD29: i | AE29: =AVERAGE(C29:I29) -> 1 | AF29: =AVERAGE(J29:P29) -> #DIV/0! | AG29: =AVERAGE(Q29:W29) -> 0 | AH29: =AVERAGE(X29:AD29) -> 1 | AI29: =AVERAGE(C29:W29) -> 0.6
A30: 27 | B30: ='1.HAFTA'!B30 -> Mehmet Cakmak | C30: i | D30: 1 | E30: 1 | F30: i | G30: 1 | H30: i | I30: i | Q30: 0 | R30: 1 | S30: 1 | T30: 1 | U30: i | V30: i | W30: i | X30: i | Y30: i | Z30: 1 | AA30: 1 | AB30: i | AC30: i | AD30: i | AE30: =AVERAGE(C30:I30) -> 1 | AF30: =AVERAGE(J30:P30) -> #DIV/0! | AG30: =AVERAGE(Q30:W30) -> 0.75 | AH30: =AVERAGE(X30:AD30) -> 1 | AI30: =AVERAGE(C30:W30) -> 0.85714286
A31: 28 | B31: ='1.HAFTA'!B31 -> Rasit Aldirmaz | C31: i | D31: 1 | E31: i | F31: i | G31: 1 | H31: i | I31: i | Q31: 1 | R31: 1 | S31: 0 | T31: 0 | U31: i | V31: i | W31: i | X31: i | Y31: i | Z31: 1 | AA31: 0 | AB31: i | AC31: i | AD31: i | AE31: =AVERAGE(C31:I31) -> 1 | AF31: =AVERAGE(J31:P31) -> #DIV/0! | AG31: =AVERAGE(Q31:W31) -> 0.5 | AH31: =AVERAGE(X31:AD31) -> 0.5 | AI31: =AVERAGE(C31:W31) -> 0.66666667
A32: 29 | B32: ='1.HAFTA'!B32 -> Tunahan Altun | C32: i | D32: 1 | E32: 1 | F32: i | G32: 1 | H32: i | I32: i | Q32: 1 | R32: 0 | S32: 1 | T32: 1 | U32: i | V32: i | W32: i | X32: i | Y32: i | Z32: 1 | AA32: 1 | AB32: i | AC32: i | AD32: i | AE32: =AVERAGE(C32:I32) -> 1 | AF32: =AVERAGE(J32:P32) -> #DIV/0! | AG32: =AVERAGE(Q32:W32) -> 0.75 | AH32: =AVERAGE(X32:AD32) -> 1 | AI32: =AVERAGE(C32:W32) -> 0.85714286
A33: 30 | B33: ='1.HAFTA'!B33 -> Yusuf Emin Doğan | C33: i | D33: 1 | E33: 1 | F33: i | G33: 1 | H33: i | I33: i | Q33: 0 | R33: 0 | S33: 0 | T33: 0 | U33: i | V33: i | W33: i | X33: i | Y33: i | Z33: 0 | AA33: 0 | AB33: i | AC33: i | AD33: i | AE33: =AVERAGE(C33:I33) -> 1 | AF33: =AVERAGE(J33:P33) -> #DIV/0! | AG33: =AVERAGE(Q33:W33) -> 0 | AH33: =AVERAGE(X33:AD33) -> 0 | AI33: =AVERAGE(C33:W33) -> 0.42857143
A34: 31 | B34: ='1.HAFTA'!B34 -> Ahmet Doğan | C34: i | D34: 1 | E34: 1 | F34: i | G34: 1 | H34: i | I34: i | Q34: 1 | R34: 1 | S34: 1 | T34: 1 | U34: i | V34: i | W34: i | X34: i | Y34: i | Z34: 1 | AA34: 1 | AB34: i | AC34: i | AD34: i | AE34: =AVERAGE(C34:I34) -> 1 | AF34: =AVERAGE(J34:P34) -> #DIV/0! | AG34: =AVERAGE(Q34:W34) -> 1 | AH34: =AVERAGE(X34:AD34) -> 1 | AI34: =AVERAGE(C34:W34) -> 1
A35: 32 | B35: ='1.HAFTA'!B35 -> Cihan Boorsma | C35: i | D35: 1 | E35: i | F35: i | G35: 1 | H35: i | I35: i | Q35: 1 | R35: 1 | S35: 1 | T35: 0 | U35: i | V35: i | W35: i | X35: i | Y35: i | Z35: 1 | AA35: 1 | AB35: i | AC35: i | AD35: i | AE35: =AVERAGE(C35:I35) -> 1 | AF35: =AVERAGE(J35:P35) -> #DIV/0! | AG35: =AVERAGE(Q35:W35) -> 0.75 | AH35: =AVERAGE(X35:AD35) -> 1 | AI35: =AVERAGE(C35:W35) -> 0.83333333
A36: 33 | B36: ='1.HAFTA'!B36 -> Mehmethan Gür | C36: i | D36: 1 | E36: 1 | F36: i | G36: 1 | H36: i | I36: i | Q36: 0 | R36: 0 | S36: 1 | T36: 1 | U36: i | V36: i | W36: i | X36: i | Y36: i | Z36: 1 | AA36: 1 | AB36: i | AC36: i | AD36: i | AE36: =AVERAGE(C36:I36) -> 1 | AF36: =AVERAGE(J36:P36) -> #DIV/0! | AG36: =AVERAGE(Q36:W36) -> 0.5 | AH36: =AVERAGE(X36:AD36) -> 1 | AI36: =AVERAGE(C36:W36) -> 0.71428571
A37: 34 | B37: ='1.HAFTA'!B37 -> Melih Taş | C37: i | D37: 1 | E37: 1 | F37: i | G37: 1 | H37: i | I37: i | Q37: 0 | R37: 0 | S37: 0 | T37: i | U37: i | V37: i | W37: i | X37: i | Y37: i | Z37: 1 | AA37: i | AB37: i | AC37: i | AD37: i | AE37: =AVERAGE(C37:I37) -> 1 | AF37: =AVERAGE(J37:P37) -> #DIV/0! | AG37: =AVERAGE(Q37:W37) -> 0 | AH37: =AVERAGE(X37:AD37) -> 1 | AI37: =AVERAGE(C37:W37) -> 0.5
A38: 35 | B38: ='1.HAFTA'!B38 -> Melih Uzun | C38: i | D38: 1 | E38: i | F38: i | G38: 1 | H38: i | I38: i | Q38: 1 | R38: 1 | S38: 1 | T38: 1 | U38: i | V38: i | W38: i | X38: i | Y38: i | Z38: 0 | AA38: 1 | AB38: i | AC38: i | AD38: i | AE38: =AVERAGE(C38:I38) -> 1 | AF38: =AVERAGE(J38:P38) -> #DIV/0! | AG38: =AVERAGE(Q38:W38) -> 1 | AH38: =AVERAGE(X38:AD38) -> 0.5 | AI38: =AVERAGE(C38:W38) -> 1
A39: 36 | B39: ='1.HAFTA'!B39 -> Mucahit Kan | C39: i | D39: 0 | E39: i | F39: i | G39: 0 | H39: i | I39: i | Q39: 0 | R39: 0 | S39: 0 | T39: 0 | U39: i | V39: i | W39: i | X39: i | Y39: i | Z39: 1 | AA39: 1 | AB39: i | AC39: i | AD39: i | AE39: =AVERAGE(C39:I39) -> 0 | AF39: =AVERAGE(J39:P39) -> #DIV/0! | AG39: =AVERAGE(Q39:W39) -> 0 | AH39: =AVERAGE(X39:AD39) -> 1 | AI39: =AVERAGE(C39:W39) -> 0
A40: 37 | B40: ='1.HAFTA'!B40 -> Oğuzhan Üzümcü | C40: i | D40: 1 | E40: 1 | F40: i | G40: 1 | H40: i | I40: i | Q40: 1 | R40: 1 | S40: 0 | T40: 1 | U40: i | V40: i | W40: i | X40: i | Y40: i | Z40: 1 | AA40: 1 | AB40: i | AC40: i | AD40: i | AE40: =AVERAGE(C40:I40) -> 1 | AF40: =AVERAGE(J40:P40) -> #DIV/0! | AG40: =AVERAGE(Q40:W40) -> 0.75 | AH40: =AVERAGE(X40:AD40) -> 1 | AI40: =AVERAGE(C40:W40) -> 0.85714286
...

Sheet 4.HAFTA
A1: =('1.HAFTA'!A1:AD1) -> TALEBE TAKİP SİSTEMİ 2024-2025 | AE1: =('1.HAFTA'!AE1:AI1) -> Amsterdam Saray
A2: 4.HAFTA | C2: SABAH NAMAZI PROGRAMLARI | J2: AKŞAM NAMAZI PROĞRAMLARI | Q2: YATSI NAMAZI PROGRAMLARI | X2: HATİM | AE2: 4.HAFTA ORTALAMALAR
A3: NO | B3: ADI SOYADI | C3: PAZARTESİ | D3: SALI | E3: ÇARŞAMBA | F3: PERŞEMBE | G3: CUMA | H3: CUMARTESİ | I3: PAZAR | J3: PAZARTESİ | K3: SALI | L3: ÇARŞAMBA | M3: PERŞEMBE | N3: CUMA | O3: CUMARTESİ | P3: PAZAR | Q3: PAZARTESİ | R3: SALI | S3: ÇARŞAMBA | T3: PERŞEMBE | U3: CUMA | V3: CUMARTESİ | W3: PAZAR | X3: PAZARTESİ | Y3: SALI | Z3: ÇARŞAMBA | AA3: PERŞEMBE | AB3: CUMA | AC3: CUMARTESİ | AD3: PAZAR | AE3: SABAH | AF3: AKŞAM | AG3: YATSI | AH3: HATİM | AI3: NAMAZ
A4: 1 | B4: ='1.HAFTA'!B4 -> Abdullah Koşar | C4: i | D4: 1 | E4: 0 | F4: i | G4: i | H4: i | I4: i | Q4: i | R4: 0 | S4: i | T4: i | U4: i | V4: i | W4: i | X4: i | Y4: i | Z4: i | AA4: i | AB4: i | AC4: i | AD4: i | AE4: =AVERAGE(C4:I4) -> 0.5 | AF4: =AVERAGE(J4:P4) -> #DIV/0! | AG4: =AVERAGE(Q4:W4) -> 0 | AH4: =AVERAGE(X4:AD4) -> #DIV/0! | AI4: =AVERAGE(C4:W4) -> 0.33333333
A5: 2 | B5: ='1.HAFTA'!B5 -> Ahmet Arif Ozmen | C5: i | D5: i | E5: i | F5: i | G5: i | H5: i | I5: i | Q5: i | R5: i | S5: i | T5: i | U5: i | V5: i | W5: i | X5: i | Y5: i | Z5: i | AA5: i | AB5: i | AC5: i | AD5: i | AE5: =AVERAGE(C5:I5) -> #DIV/0! | AF5: =AVERAGE(J5:P5) -> #DIV/0! | AG5: =AVERAGE(Q5:W5) -> #DIV/0! | AH5: =AVERAGE(X5:AD5) -> #DIV/0! | AI5: =AVERAGE(C5:W5) -> #DIV/0!
A6: 3 | B6: ='1.HAFTA'!B6 -> Alihan Uysal | C6: i | D6: 1 | E6: 1 | F6: 1 | G6: i | H6: i | I6: i | Q6: i | R6: 0 | S6: i | T6: i | U6: i | V6: i | W6: i | X6: i | Y6: i | Z6: i | AA6: 1 | AB6: i | AC6: i | AD6: i | AE6: =AVERAGE(C6:I6) -> 1 | AF6: =AVERAGE(J6:P6) -> #DIV/0! | AG6: =AVERAGE(Q6:W6) -> 0 | AH6: =AVERAGE(X6:AD6) -> 1 | AI6: =AVERAGE(C6:W6) -> 0.75
A7: 4 | B7: ='1.HAFTA'!B7 -> Ammaar Ahmad | C7: i | D7: 1 | E7: 1 | F7: 1 | G7: i | H7: i | I7: i | Q7: i | R7: 1 | S7: i | T7: i | U7: i | V7: i | W7: i | X7: i | Y7: i | Z7: i | AA7: 1 | AB7: i | AC7: i | AD7: i | AE7: =AVERAGE(C7:I7) -> 1 | AF7: =AVERAGE(J7:P7) -> #DIV/0! | AG7: =AVERAGE(Q7:W7) -> 1 | AH7: =AVERAGE(X7:AD7) -> 1 | AI7: =AVERAGE(C7:W7) -> 1
A8: 5 | B8: ='1.HAFTA'!B8 -> Ekrem Altıntaş | C8: i | D8: 1 | E8: 0 | F8: 1 | G8: i | H8: i | I8: i | Q8: i | R8: 1 | S8: i | T8: i | U8: i | V8: i | W8: i | X8: i | Y8: i | Z8: i | AA8: 1 | AB8: i | AC8: i | AD8: i | AE8: =AVERAGE(C8:I8) -> 0.66666667 | AF8: =AVERAGE(J8:P8) -> #DIV/0! | AG8: =AVERAGE(Q8:W8) -> 1 | AH8: =AVERAGE(X8:AD8) -> 1 | AI8: =AVERAGE(C8:W8) -> 0.75
A9: 6 | B9: ='1.HAFTA'!B9 -> Emirhan Sak | C9: i | D9: 1 | E9: 0 | F9: 1 | G9: i | H9: i | I9: i | Q9: i | R9: 1 | S9: i | T9: i | U9: i | V9: i | W9: i | X9: i | Y9: i | Z9: i | AA9: 1 | AB9: i | AC9: i | AD9: i | AE9: =AVERAGE(C9:I9) -> 0.66666667 | AF9: =AVERAGE(J9:P9) -> #DIV/0! | AG9: =AVERAGE(Q9:W9) -> 1 | AH9: =AVERAGE(X9:AD9) -> 1 | AI9: =AVERAGE(C9:W9) -> 0.75 | AK9: 45740 | AL9: 45746
A10: 7 | B10: ='1.HAFTA'!B10 -> Eymen Göğebakan | C10: i | D10: 1 | E10: 0 | F10: 0 | G10: i | H10: i | I10: i | Q10: i | R10: 1 | S10: i | T10: i | U10: i | V10: i | W10: i | X10: i | Y10: i | Z10: i | AA10: i | AB10: i | AC10: i | AD10: i | AE10: =AVERAGE(C10:I10) -> 0.33333333 | AF10: =AVERAGE(J10:P10) -> #DIV/0! | AG10: =AVERAGE(Q10:W10) -> 1 | AH10: =AVERAGE(X10:AD10) -> #DIV/0! | AI10: =AVERAGE(C10:W10) -> 0.5
A11: 8 | B11: ='1.HAFTA'!B11 -> Mehmet Sak | C11: i | D11: 1 | E11: 1 | F11: 1 | G11: i | H11: i | I11: i | Q11: i | R11: 1 | S11: i | T11: i | U11: i | V11: i | W11: i | X11: i | Y11: i | Z11: i | AA11: 1 | AB11: i | AC11: i | AD11: i | AE11: =AVERAGE(C11:I11) -> 1 | AF11: =AVERAGE(J11:P11) -> #DIV/0! | AG11: =AVERAGE(Q11:W11) -> 1 | AH11: =AVERAGE(X11:AD11) -> 1 | AI11: =AVERAGE(C11:W11) -> 1
A12: 9 | B12: ='1.HAFTA'!B12 -> Mohammed Abdi Hakim | C12: i | D12: i | E12: 1 | F12: 1 | G12: i | H12: i | I12: i | Q12: i | R12: 0 | S12: i | T12: i | U12: i | V12: i | W12: i | X12: i | Y12: i | Z12: i | AA12: 1 | AB12: i | AC12: i | AD12: i | AE12: =AVERAGE(C12:I12) -> 1 | AF12: =AVERAGE(J12:P12) -> #DIV/0! | AG12: =AVERAGE(Q12:W12) -> 0 | AH12: =AVERAGE(X12:AD12) -> 1 | AI12: =AVERAGE(C12:W12) -> 0.66666667
A13: 10 | B13: ='1.HAFTA'!B13 -> Rıdvan Sönmez | C13: i | D13: 1 | E13: 0 | F13: 1 | G13: i | H13: i | I13: i | Q13: i | R13: 1 | S13: i | T13: i | U13: i | V13: i | W13: i | X13: i | Y13: i | Z13: i | AA13: 1 | AB13: i | AC13: i | AD13: i | AE13: =AVERAGE(C13:I13) -> 0.66666667 | AF13: =AVERAGE(J13:P13) -> #DIV/0! | AG13: =AVERAGE(Q13:W13) -> 1 | AH13: =AVERAGE(X13:AD13) -> 1 | AI13: =AVERAGE(C13:W13) -> 0.75
A14: 11 | B14: ='1.HAFTA'!B14 -> Tayyip Sönmez | C14: i | D14: i | E14: i | F14: i | G14: i | H14: i | I14: i | Q14: i | R14: i | S14: i | T14: i | U14: i | V14: i | W14: i | X14: i | Y14: i | Z14: i | AA14: i | AB14: i | AC14: i | AD14: i | AE14: =AVERAGE(C14:I14) -> #DIV/0! | AF14: =AVERAGE(J14:P14) -> #DIV/0! | AG14: =AVERAGE(Q14:W14) -> #DIV/0! | AH14: =AVERAGE(X14:AD14) -> #DIV/0! | AI14: =AVERAGE(C14:W14) -> #DIV/0!
A15: 12 | B15: ='1.HAFTA'!B15 -> Waffi Talib | C15: i | D15: i | E15: i | F15: 1 | G15: i | H15: i | I15: i | Q15: i | R15: i | S15: i | T15: i | U15: i | V15: i | W15: i | X15: i | Y15: i | Z15: i | AA15: 1 | AB15: i | AC15: i | AD15: i | AE15: =AVERAGE(C15:I15) -> 1 | AF15: =AVERAGE(J15:P15) -> #DIV/0! | AG15: =AVERAGE(Q15:W15) -> #DIV/0! | AH15: =AVERAGE(X15:AD15) -> 1 | AI15: =AVERAGE(C15:W15) -> 1
A16: 13 | B16: ='1.HAFTA'!B16 -> Ahmet Enes Küçüktepe | C16: i | D16: 1 | E16: 0 | F16: 0 | G16: i | H16: i | I16: i | Q16: i | R16: I | S16: i | T16: i | U16: i | V16: i | W16: i | X16: i | Y16: i | Z16: i | AA16: i | AB16: i | AC16: i | AD16: i | AE16: =AVERAGE(C16:I16) -> 0.33333333 | AF16: =AVERAGE(J16:P16) -> #DIV/0! | AG16: =AVERAGE(Q16:W16) -> #DIV/0! | AH16: =AVERAGE(X16:AD16) -> #DIV/0! | AI16: =AVERAGE(C16:W16) -> 0.33333333
A17: 14 | B17: ='1.HAFTA'!B17 -> Abdulkerim Karazehir | C17: i | D17: 1 | E17: 1 | F17: 0 | G17: i | H17: i | I17: i | Q17: i | R17: 0 | S17: i | T17: i | U17: i | V17: i | W17: i | X17: i | Y17: i | Z17: i | AA17: 1 | AB17: i | AC17: i | AD17: i | AE17: =AVERAGE(C17:I17) -> 0.66666667 | AF17: =AVERAGE(J17:P17) -> #DIV/0! | AG17: =AVERAGE(Q17:W17) -> 0 | AH17: =AVERAGE(X17:AD17) -> 1 | AI17: =AVERAGE(C17:W17) -> 0.5
A18: 15 | B18: ='1.HAFTA'!B18 -> Berat Basan | C18: i | D18: 0 | E18: 0 | F18: 0 | G18: i | H18: i | I18: i | Q18: i | R18: i | S18: i | T18: i | U18: i | V18: i | W18: i | X18: i | Y18: i | Z18: i | AA18: 1 | AB18: i | AC18: i | AD18: i | AE18: =AVERAGE(C18:I18) -> 0 | AF18: =AVERAGE(J18:P18) -> #DIV/0! | AG18: =AVERAGE(Q18:W18) -> #DIV/0! | AH18: =AVERAGE(X18:AD18) -> 1 | AI18: =AVERAGE(C18:W18) -> 0
A19: 16 | B19: ='1.HAFTA'!B19 -> Burhan Çevik | C19: i | D19: 1 | E19: 0 | F19: i | G19: i | H19: i | I19: i | Q19: i | R19: 0 | S19: i | T19: i | U19: i | V19: i | W19: i | X19: i | Y19: i | Z19: i | AA19: 1 | AB19: i | AC19: i | AD19: i | AE19: =AVERAGE(C19:I19) -> 0.5 | AF19: =AVERAGE(J19:P19) -> #DIV/0! | AG19: =AVERAGE(Q19:W19) -> 0 | AH19: =AVERAGE(X19:AD19) -> 1 | AI19: =AVERAGE(C19:W19) -> 0.33333333
A20: 17 | B20: ='1.HAFTA'!B20 -> Enes Bakar | C20: i | D20: b | E20: 0 | F20: 0 | G20: i | H20: i | I20: i | Q20: i | R20: 0 | S20: i | T20: i | U20: i | V20: i | W20: i | X20: i | Y20: i | Z20: i | AA20: 1 | AB20: i | AC20: i | AD20: i | AE20: =AVERAGE(C20:I20) -> 0 | AF20: =AVERAGE(J20:P20) -> #DIV/0! | AG20: =AVERAGE(Q20:W20) -> 0 | AH20: =AVERAGE(X20:AD20) -> 1 | AI20: =AVERAGE(C20:W20) -> 0
A21: 18 | B21: ='1.HAFTA'!B21 -> Hüseyin Özdemir | C21: i | D21: 1 | E21: 0 | F21: 1 | G21: i | H21: i | I21: i | Q21: i | R21: 0 | S21: i | T21: i | U21: i | V21: i | W21: i | X21: i | Y21: i | Z21: i | AA21: 1 | AB21: i | AC21: i | AD21: i | AE21: =AVERAGE(C21:I21) -> 0.66666667 | AF21: =AVERAGE(J21:P21) -> #DIV/0! | AG21: =AVERAGE(Q21:W21) -> 0 | AH21: =AVERAGE(X21:AD21) -> 1 | AI21: =AVERAGE(C21:W21) -> 0.5
A22: 19 | B22: ='1.HAFTA'!B22 -> Yahya Yıldız | C22: i | D22: 1 | E22: 1 | F22: 1 | G22: i | H22: i | I22: i | Q22: i | R22: 0 | S22: i | T22: i | U22: i | V22: i | W22: i | X22: i | Y22: i | Z22: i | AA22: 1 | AB22: i | AC22: i | AD22: i | AE22: =AVERAGE(C22:I22) -> 1 | AF22: =AVERAGE(J22:P22) -> #DIV/0! | AG22: =AVERAGE(Q22:W22) -> 0 | AH22: =AVERAGE(X22:AD22) -> 1 | AI22: =AVERAGE(C22:W22) -> 0.75
A23: 20 | B23: ='1.HAFTA'!B23 -> Yakup Karazehir | C23: i | D23: 1 | E23: 1 | F23: 1 | G23: i | H23: i | I23: i | Q23: i | R23: 1 | S23: i | T23: i | U23: i | V23: i | W23: i | X23: i | Y23: i | Z23: i | AA23: 1 | AB23: i | AC23: i | AD23: i | AE23: =AVERAGE(C23:I23) -> 1 | AF23: =AVERAGE(J23:P23) -> #DIV/0! | AG23: =AVERAGE(Q23:W23) -> 1 | AH23: =AVERAGE(X23:AD23) -> 1 | AI23: =AVERAGE(C23:W23) -> 1
A24: 21 | B24: ='1.HAFTA'!B24 -> Abdussamed Arslan | C24: i | D24: 1 | E24: 1 | F24: 0 | G24: i | H24: i | I24: i | Q24: i | R24: 0 | S24: i | T24: i | U24: i | V24: i | W24: i | X24: i | Y24: i | Z24: i | AA24: 0 | AB24: i | AC24: i | AD24: i | AE24: =AVERAGE(C24:I24) -> 0.66666667 | AF24: =AVERAGE(J24:P24) -> #DIV/0! | AG24: =AVERAGE(Q24:W24) -> 0 | AH24: =AVERAGE(X24:AD24) -> 0 | AI24: =AVERAGE(C24:W24) -> 0.5
A25: 22 | B25: ='1.HAFTA'!B25 -> Abdussamed Erdem | C25: i | D25: 1 | E25: 0 | F25: 1 | G25: i | H25: i | I25: i | Q25: i | R25: 0 | S25: i | T25: i | U25: i | V25: i | W25: i | X25: i | Y25: i | Z25: i | AA25: i | AB25: i | AC25: i | AD25: i | AE25: =AVERAGE(C25:I25) -> 0.66666667 | AF25: =AVERAGE(J25:P25) -> #DIV/0! | AG25: =AVERAGE(Q25:W25) -> 0 | AH25: =AVERAGE(X25:AD25) -> #DIV/0! | AI25: =AVERAGE(C25:W25) -> 0.5
A26: 23 | B26: ='1.HAFTA'!B26 -> Ahmet Boyacıoğlu | C26: i | D26: i | E26: 0 | F26: i | G26: i | H26: i | I26: i | Q26: i | R26: i | S26: i | T26: i | U26: i | V26: i | W26: i | X26: i | Y26: i | Z26: i | AA26: 1 | AB26: i | AC26: i | AD26: i | AE26: =AVERAGE(C26:I26) -> 0 | AF26: =AVERAGE(J26:P26) -> #DIV/0! | AG26: =AVERAGE(Q26:W26) -> #DIV/0! | AH26: =AVERAGE(X26:AD26) -> 1 | AI26: =AVERAGE(C26:W26) -> 0
A27: 24 | B27: ='1.HAFTA'!B27 -> Ahmet Kökçü | C27: i | D27: 1 | E27: 1 | F27: 1 | G27: i | H27: i | I27: i | Q27: i | R27: i | S27: i | T27: i | U27: i | V27: i | W27: i | X27: i | Y27: i | Z27: i | AA27: 1 | AB27: i | AC27: i | AD27: i | AE27: =AVERAGE(C27:I27) -> 1 | AF27: =AVERAGE(J27:P27) -> #DIV/0! | AG27: =AVERAGE(Q27:W27) -> #DIV/0! | AH27: =AVERAGE(X27:AD27) -> 1 | AI27: =AVERAGE(C27:W27) -> 1
A28: 25 | B28: ='1.HAFTA'!B28 -> Fatih Burcu | C28: i | D28: 1 | E28: 1 | F28: 1 | G28: i | H28: i | I28: i | Q28: i | R28: i | S28: i | T28: i | U28: i | V28: i | W28: i | X28: i | Y28: i | Z28: i | AA28: i | AB28: i | AC28: i | AD28: i | AE28: =AVERAGE(C28:I28) -> 1 | AF28: =AVERAGE(J28:P28) -> #DIV/0! | AG28: =AVERAGE(Q28:W28) -> #DIV/0! | AH28: =AVERAGE(X28:AD28) -> #DIV/0! | AI28: =AVERAGE(C28:W28) -> 1
A29: 26 | B29: ='1.HAFTA'!B29 -> Fehmi Kütük | C29: i | D29: 1 | E29: 0 | F29: 0 | G29: i | H29: i | I29: i | Q29: i | R29: i | S29: i | T29: i | U29: i | V29: i | W29: i | X29: i | Y29: i | Z29: i | AA29: 1 | AB29: i | AC29: i | AD29: i | AE29: =AVERAGE(C29:I29) -> 0.33333333 | AF29: =AVERAGE(J29:P29) -> #DIV/0! | AG29: =AVERAGE(Q29:W29) -> #DIV/0! | AH29: =AVERAGE(X29:AD29) -> 1 | AI29: =AVERAGE(C29:W29) -> 0.33333333
A30: 27 | B30: ='1.HAFTA'!B30 -> Mehmet Cakmak | C30: i | D30: 1 | E30: 1 | F30: 1 | G30: i | H30: i | I30: i | Q30: i | R30: 0 | S30: i | T30: i | U30: i | V30: i | W30: i | X30: i | Y30: i | Z30: i | AA30: i | AB30: i | AC30: i | AD30: i | AE30: =AVERAGE(C30:I30) -> 1 | AF30: =AVERAGE(J30:P30) -> #DIV/0! | AG30: =AVERAGE(Q30:W30) -> 0 | AH30: =AVERAGE(X30:AD30) -> #DIV/0! | AI30: =AVERAGE(C30:W30) -> 0.75
A31: 28 | B31: ='1.HAFTA'!B31 -> Rasit Aldirmaz | C31: i | D31: 1 | E31: 0 | F31: 1 | G31: i | H31: i | I31: i | Q31: i | R31: 0 | S31: i | T31: i | U31: i | V31: i | W31: i | X31: i | Y31: i | Z31: i | AA31: 0 | AB31: i | AC31: i | AD31: i | AE31: =AVERAGE(C31:I31) -> 0.66666667 | AF31: =AVERAGE(J31:P31) -> #DIV/0! | AG31: =AVERAGE(Q31:W31) -> 0 | AH31: =AVERAGE(X31:AD31) -> 0 | AI31: =AVERAGE(C31:W31) -> 0.5
A32: 29 | B32: ='1.HAFTA'!B32 -> Tunahan Altun | C32: i | D32: i | E32: 1 | F32: 1 | G32: i | H32: i | I32: i | Q32: i | R32: i | S32: i | T32: i | U32: i | V32: i | W32: i | X32: i | Y32: i | Z32: i | AA32: i | AB32: i | AC32: i | AD32: i | AE32: =AVERAGE(C32:I32) -> 1 | AF32: =AVERAGE(J32:P32) -> #DIV/0! | AG32: =AVERAGE(Q32:W32) -> #DIV/0! | AH32: =AVERAGE(X32:AD32) -> #DIV/0! | AI32: =AVERAGE(C32:W32) -> 1
A33: 30 | B33: ='1.HAFTA'!B33 -> Yusuf Emin Doğan | C33: i | D33: 1 | E33: 0 | F33: 0 | G33: i | H33: i | I33: i | Q33: i | R33: 0 | S33: i | T33: i | U33: i | V33: i | W33: i | X33: i | Y33: i | Z33: i | AA33: 1 | AB33: i | AC33: i | AD33: i | AE33: =AVERAGE(C33:I33) -> 0.33333333 | AF33: =AVERAGE(J33:P33) -> #DIV/0! | AG33: =AVERAGE(Q33:W33) -> 0 | AH33: =AVERAGE(X33:AD33) -> 1 | AI33: =AVERAGE(C33:W33) -> 0.25
A34: 31 | B34: ='1.HAFTA'!B34 -> Ahmet Doğan | C34: i | D34: 1 | E34: 1 | F34: 1 | G34: i | H34: i | I34: i | Q34: i | R34: i | S34: i | T34: i | U34: i | V34: i | W34: i | X34: i | Y34: i | Z34: i | AA34: 0 | AB34: i | AC34: i | AD34: i | AE34: =AVERAGE(C34:I34) -> 1 | AF34: =AVERAGE(J34:P34) -> #DIV/0! | AG34: =AVERAGE(Q34:W34) -> #DIV/0! | AH34: =AVERAGE(X34:AD34) -> 0 | AI34: =AVERAGE(C34:W34) -> 1
